Workbook

Sheet Measurement sheet
A1: Name of Work :- Renovation & Repairing of Circuit House at Bokakhat Co District.
A2: ITEM NO. | B2: Sl No | C2: DESCRIPTION OF ITEM | D2: Nos | E2: Nos | F2: L | G2: B | H2: D/H | I2: Qty | J2: UNIT | K2: RATE ₹ | L2: AMOUNT
A3: 1 | B3: 15.7 | C3: Demolishing brick work manually/ by mechanical means including stacking of serviceable material and disposal of unserviceable material within 50 metres lead as per direction of Engineer-in-charge. 15.7.4 in cement mortar
C4: In cement mortar | D4: 1 | F4: 10.45 | G4: 0.122 | H4: 0.78 | I4: =H4*G4*F4*D4 -> 0.99
D5: 1 | F5: 2.3 | G5: 0.122 | H5: 2.1 | I5: =H5*G5*F5*D5 -> 0.59
G6: (T)= | I6: =SUM(I4:I5) -> 1.58 | J6: Cum | K6: 1698.45 | L6: =K6*I6 -> 2683.55
A7: 2 | B7: 15.23.1 | C7: Dismantling tile work in floors and roofs laid in cement mortar including stacking material within 50 metres lead. 15.23.1 For thickness of tiles 10 mm to 25 mm | N7: =5.95+3.1 -> 9.05
C8: Ground floor.Toilet | D8: 3 | F8: 3.15 | G8: 1.45 | I8: =G8*F8*D8 -> 13.7
D9: 1 | F9: 2.05 | G9: 1.45 | I9: =G9*F9*D9 -> 2.97
D10: 3 | F10: 9.2 | G10: 1.5 | I10: =G10*F10*D10 -> 41.4
D11: 1 | F11: 7 | G11: 2.1 | I11: =G11*F11*D11 -> 14.7
C12: First floor.Toilet | D12: 4 | F12: 3.8 | G12: 1.8 | I12: =G12*F12*D12 -> 27.36
D13: 4 | F13: 11.2 | G13: 2.1 | I13: =G13*F13*D13 -> 94.08
G14: (T)= | I14: =SUM(I8:I13) -> 194.21 | J14: Sqm | K14: 60.5 | L14: =K14*I14 -> 11749.71
A15: 3 | B15: 15.28 | C15: Dismantling roofing including ridges, hips, valleys and gutters etc., and stacking the material within 50 metres lead of: 15.28.1G.S. Sheet
D16: 2 | F16: 2.1 | G16: 0.85 | I16: =G16*F16*D16 -> 3.57 | J16: Sqm | K16: 136 | L16: =K16*I16 -> 485.52
A17: 4 | B17: 2.25 | C17: Filling available excavated earth (excluding rock) in trenches, plinth, sides of foundations etc. in layers not exceeding 20cm in depth, consolidating each deposited layer by ramming and watering, lead up to 50 m and lift upto 1.5 m. | O17: 9101136098
D18: 1 | F18: 7.7 | G18: 2.6 | H18: 0.65 | I18: =H18*G18*F18*D18 -> 13.01 | J18: Cum | K18: 253.95 | L18: =K18*I18 -> 3303.89
A19: 5 | B19: 11.2 | C19: Dry brick on edge flooring in required pattern with bricks of class designation 7.5 on a bed of 12 mm mud mortar, including filling joints with Jamuna sand, with common burnt clay non modular bricks.
D20: 1 | F20: 6 | G20: 1.65 | I20: =G20*F20*D20 -> 9.9 | J20: Sqm | K20: 733.3 | L20: =K20*I20 -> 7259.67
A21: 6 | B21: 11.5 | C21: 62 mm thick cement concrete flooring with concrete hardener topping, under layer 50 mm thick cement concrete 1:2:4 (1 cement : 2 coarse sand : 4 graded stone aggregate 20mm nominal size) and top layer 12mm thick cement hardener consisting of mix 1:2 (1 cement hardener mix : 2 graded stone aggregate, 6mm nominal size) by volume, hardening compound mixed @ 2 litre per 50 kg of cement or as per manufacture’s specifications. This includes cost of cement slurry, but excluding the cost of nosing of steps etc. complete.
D22: 1 | F22: 6 | G22: 1.65 | I22: =G22*F22*D22 -> 9.9 | J22: Sqm | K22: 928.65 | L22: =K22*I22 -> 9193.64
A23: 7 | B23: 11.41 | C23: Providing and laying vitrified floor tiles in different sizes (thickness to be specified by the manufacturer) with water absorption less than 0.08% and conforming to IS: 15622, of approved make, in all colours and shades, laid on 20mm thick cement mortar 1:4 (1 cement : 4 coarse sand), jointing with grey cement slurry @ 3.3 kg/ sqm including grouting the joints with white cement and matching pigments etc., complete. 11.41.2 Size of Tile 600x600 mm
C24: Existing Kitchen | D24: 1 | F24: 6 | G24: 3.55 | I24: =G24*F24*D24 -> 21.3
C25: Chawkidar room | D25: 1 | F25: 2.95 | G25: 3.6 | I25: =G25*F25*D25 -> 10.62
C26: Verandah | D26: 1 | F26: 4.25 | G26: 7.5 | I26: =G26*F26*D26 -> 31.88
C27: Ground floor toilet | D27: 3 | F27: 3.15 | G27: 1.45 | I27: =G27*F27*D27 -> 13.7
D28: 1 | F28: 2.05 | G28: 1.45 | I28: =G28*F28*D28 -> 2.97
C29: First floor toilet | D29: 4 | F29: 3.8 | G29: 1.8 | I29: =G29*F29*D29 -> 27.36
C30: Dormitory | D30: 1 | F30: 9.15 | G30: 6 | I30: =G30*F30*D30 -> 54.9
D31: 1 | F31: 6.4 | G31: 3.5 | I31: =G31*F31*D31 -> 22.4
D32: 1 | F32: 6.4 | G32: 1.85 | I32: =G32*F32*D32 -> 11.84
C33: Dormitory Front step | D33: 4 | F33: 3.3 | G33: 0.35 | I33: =G33*F33*D33 -> 4.62
D34: 4 | F34: 3.3 | G34: 0.16 | I34: =G34*F34*D34 -> 2.11
G35: (T)= | I35: =SUM(I24:I34) -> 203.7 | J35: Sqm | K35: 1416.65 | L35: =K35*I35 -> 288571.61
A36: 8 | B36: 8.31 | C36: Providing and fixing Ist quality ceramic glazed wall tiles conforming to IS: 15622 (thickness to be specified by the manufacturer), of approved make, in all colours, shades except burgundy, bottle green, black of any size as approved by Engineer-in-Charge, in skirting, risers of steps and dados, over 12 mm thick bed of cement mortar 1:3 (1 cement : 3 coarse sand) and jointing with grey cement slurry @ 3.3kg per sqm, including pointing in white cement mixed with pigment of matching shade complete.
C37: Ground floor toilet | D37: 3 | F37: 9.2 | G37: 1.5 | I37: =G37*F37*D37 -> 41.4
D38: 1 | F38: 7 | G38: 2.1 | I38: =G38*F38*D38 -> 14.7
C39: First floor toilet | D39: 4 | F39: 11.2 | G39: 2.1 | I39: =G39*F39*D39 -> 94.08
C40: Dormitory toilet | D40: 4 | F40: 6.9 | G40: 2.1 | I40: =G40*F40*D40 -> 57.96
...

Sheet cs
A1: COMPARATIVE STATEMENT (MODULAR KITCHEN)
A2: Name of Work :- Renovation & Repair of Circuit House at Bokakhat Co District.
A3: Sl No. | C3: 1 | G3: 2 | K3: 3 | O3: Remarks
A4: Name of the quotation holder with address | C4: Royal Traders, Bokakhat | G4: Om Narayani hardware, Bokakhat | K4: Antique Orient Home decor, Guwahati
A5: Sl No. | B5: Description of items | C5: Qnty. | D5: Base Amount (in Rs.) | E5: Amount with 18% GST (in Rs,) | F5: Total Amount | G5: Qnty. | H5: Base Amount (in Rs.) | I5: Amount with 18% GST (in Rs,) | J5: Total Amount | K5: Qnty. | L5: Base Amount (in Rs.) | M5: Amount with 18% GST (in Rs,) | N5: Total Amount
A6: 1 | B6: Modular kitchen | C6: 1 | D6: 474534 | E6: =D6*0.18 -> 85416.12 | F6: =ROUND(E6+D6,0) -> 559950 | G6: 1 | H6: 503814 | I6: =H6*0.18 -> 90686.52 | J6: =ROUND(I6+H6,-2) -> 594500 | K6: 1 | L6: 693898 | M6: =L6*0.18 -> 124901.64 | N6: =ROUND(M6+L6,-2) -> 818800 | O6: Lowest Rate is indicate by (L1)
B7: Total | F7: =F6 -> 559950 | J7: =J6 -> 594500 | N7: =N6 -> 818800
A8: Position | F8: L1 | J8: L2 | N8: L3
B13: Junior Engineer, PW (B&NH)D | G13: Asstt. Executive Engineer, PW (B&NH)D
B14: Bokakhat & Dergaon Territorial | G14: Bokakhat & Dergaon Territorial
B15: Building Sub- Division, Bokakhat | G15: Building Sub- Division, Bokakhat

Sheet BOQ1
A1: Name of Work :- Renovation & Repair of Circuit House at Bokakhat Co District.
A2: Civil works (A)
A3: ITEM NO. | B3: Sl No | C3: DESCRIPTION OF ITEM | J3: Qty | K3: UNIT | L3: RATE ₹ | M3: AMOUNT
A4: 1 | B4: 15.7 | C4: Demolishing brick work manually/ by mechanical means including stacking of serviceable material and disposal of unserviceable material within 50 metres lead as per direction of Engineer-in-charge.15.7.4 in cement mortar | J4: ='Measurement sheet'!I6 -> 1.58 | K4: ='Measurement sheet'!J6 -> Cum | L4: ='Measurement sheet'!K6 -> 1698.45 | M4: ='Measurement sheet'!L6 -> 2683.55 | P4: =+J4*L4 -> 2683.55
A5: 2 | B5: 15.23.1 | C5: Dismantling tile work in floors and roofs laid in cement mortar including stacking material within 50 metres lead. 15.23.1 For thickness of tiles 10 mm to 25 mm | J5: ='Measurement sheet'!I14 -> 194.21 | K5: ='Measurement sheet'!J14 -> Sqm | L5: ='Measurement sheet'!K14 -> 60.5 | M5: ='Measurement sheet'!L14 -> 11749.71 | O5: =5.95+3.1 -> 9.05
A6: 3 | B6: 15.28 | C6: Dismantling roofing including ridges, hips, valleys and gutters etc., and stacking the material within 50 metres lead of: 15.28.1G.S. Sheet | J6: ='Measurement sheet'!I16 -> 3.57 | K6: ='Measurement sheet'!J16 -> Sqm | L6: ='Measurement sheet'!K16 -> 136 | M6: ='Measurement sheet'!L16 -> 485.52
A7: 4 | B7: 2.25 | C7: Filling available excavated earth (excluding rock) in trenches, plinth, sides of foundations etc. in layers not exceeding 20cm in depth, consolidating each deposited layer by ramming and watering, lead up to 50 m and lift upto 1.5 m. | J7: ='Measurement sheet'!I18 -> 13.01 | K7: ='Measurement sheet'!J18 -> Cum | L7: ='Measurement sheet'!K18 -> 253.95 | M7: ='Measurement sheet'!L18 -> 3303.89
A8: 5 | B8: 11.2 | C8: Dry brick on edge flooring in required pattern with bricks of class designation 7.5 on a bed of 12 mm mud mortar, including filling joints with Jamuna sand, with common burnt clay non modular bricks. | J8: ='Measurement sheet'!I20 -> 9.9 | K8: ='Measurement sheet'!J20 -> Sqm | L8: ='Measurement sheet'!K20 -> 733.3 | M8: ='Measurement sheet'!L20 -> 7259.67
A9: 6 | B9: 11.5 | C9: 62 mm thick cement concrete flooring with concrete hardener topping, under layer 50 mm thick cement concrete 1:2:4 (1 cement : 2 coarse sand : 4 graded stone aggregate 20mm nominal size) and top layer 12mm thick cement hardener consisting of mix 1:2 (1 cement hardener mix : 2 graded stone aggregate, 6mm nominal size) by volume, hardening compound mixed @ 2 litre per 50 kg of cement or as per manufacture’s specifications. This includes cost of cement slurry, but excluding the cost of nosing of steps etc. complete. | J9: ='Measurement sheet'!I22 -> 9.9 | K9: ='Measurement sheet'!J22 -> Sqm | L9: ='Measurement sheet'!K22 -> 928.65 | M9: ='Measurement sheet'!L22 -> 9193.64
A10: 7 | B10: 11.41 | C10: Providing and laying vitrified floor tiles in different sizes (thickness to be specified by the manufacturer) with water absorption less than 0.08% and conforming to IS: 15622, of approved make, in all colours and shades, laid on 20mm thick cement mortar 1:4 (1 cement : 4 coarse sand), jointing with grey cement slurry @ 3.3 kg/ sqm including grouting the joints with white cement and matching pigments etc., complete. 11.41.2 Size of Tile 600x600 mm. | J10: ='Measurement sheet'!I35 -> 203.7 | K10: ='Measurement sheet'!J35 -> Sqm | L10: ='Measurement sheet'!K35 -> 1416.65 | M10: ='Measurement sheet'!L35 -> 288571.61
A11: 8 | B11: 8.31 | C11: Providing and fixing Ist quality ceramic glazed wall tiles conforming to IS: 15622 (thickness to be specified by the manufacturer), of approved make, in all colours, shades except burgundy, bottle green, black of any size as approved by Engineer-in-Charge, in skirting, risers of steps and dados, over 12 mm thick bed of cement mortar 1:3 (1 cement : 3 coarse sand) and jointing with grey cement slurry @ 3.3kg per sqm, including pointing in white cement mixed with pigment of matching shade complete. | J11: ='Measurement sheet'!I41 -> 208.14 | K11: ='Measurement sheet'!J41 -> Sqm | L11: ='Measurement sheet'!K41 -> 1063.45 | M11: ='Measurement sheet'!L41 -> 221346.48
A12: 9 | B12: 13.26 | C12: Providing and applying plaster of paris putty of 2 mm thickness over plastered surface to prepare the surface even and smooth complete. | J12: ='Measurement sheet'!I61 -> 559.89 | K12: ='Measurement sheet'!J61 -> Sqm | L12: ='Measurement sheet'!K61 -> 214.3 | M12: ='Measurement sheet'!L61 -> 119984.43
A13: 10 | B13: 13.48A | C13: Finishing walls with 100% Premium acrylic emulsion paint having VOC less than 50 gm/litre and UV resistance as per IS 15489:2004, Alkali & fungal resistance, dirt resistance exterior paint of required shade (Company Depot Tinted) with silicon additives. 13.48A.1 New work (Two or more coats applied @ 1.43 litre/ 10 sqm. Over and including priming coat of exterior primer applied @ 0.90 litre/10 sqm. | J13: ='Measurement sheet'!I81 -> 559.89 | K13: ='Measurement sheet'!J81 -> Sqm | L13: ='Measurement sheet'!K81 -> 154.45 | M13: ='Measurement sheet'!L81 -> 86475.01
A14: 11 | B14: 10.17 | C14: Providing and fixing M.S. fan clamp type I or II of 16 mm dia M.S. bar, bent to shape with hooked ends in R.C.C. slabs or beams during laying, including painting the exposed portion of loop, all as per standard design complete. | J14: ='Measurement sheet'!I83 -> 2 | K14: ='Measurement sheet'!J83 -> Each | L14: ='Measurement sheet'!K83 -> 185.95 | M14: ='Measurement sheet'!L83 -> 371.9
A15: 12 | B15: 10.14 | C15: Providing and fixing pressed steel door frames conforming to IS: 4351, manufactured from commercial mild steel sheet of 1.60 mm thickness, including hinges, jamb, lock jamb, bead and if required angle threshold of mild steel angle of section 50x25 mm, or base ties of 1.60 mm, pressed mild steel welded or rigidly fixed together by mechanical means, including M.S. pressed butt hinges 2.5 mm thick with mortar guards, lock strike-plate and shock absorbers as specified and applying a coat of approved steel primer after pre-treatment of the surface as directed by Engineer-in-charge: 10.14.1.1 Fixing with adjustable lugs with split end tail to each jamb | J15: ='Measurement sheet'!I85 -> 10.5 | K15: ='Measurement sheet'!J85 -> Rm | L15: ='Measurement sheet'!K85 -> 444.5 | M15: ='Measurement sheet'!L85 -> 4667.25
A16: 13 | B16: 9.2 | C16: Providing and fixing ISI marked flush door shutters conforming to IS : 2202 (Part I) decorative type, core of block board construction with frame of 1st class hard wood and well matched teak 3 ply veneering with vertical grains or cross bands and face veneers on both faces of shutters. 9.20.1 35 mm thick including ISI marked Stainless Steel butt hinges with necessary screws. | J16: ='Measurement sheet'!I87 -> 4.2 | K16: ='Measurement sheet'!J87 -> Sqm | L16: ='Measurement sheet'!K87 -> 3086.1 | M16: ='Measurement sheet'!L87 -> 12961.62
A17: 14 | B17: 9.96 | C17: Providing and fixing aluminium sliding door bolts, ISI marked anodised (anodic coating not less than grade AC 10 as per IS : 1868), transparent or dyed to required colour or shade, with nuts and screws etc. complete 9.96.1 300x16 mm | J17: ='Measurement sheet'!I89 -> 4 | K17: ='Measurement sheet'!J89 -> Each | L17: ='Measurement sheet'!K89 -> 260.3 | M17: ='Measurement sheet'!L89 -> 1041.2
A18: 15 | B18: 9.97 | C18: Providing and fixing aluminium tower bolts, ISI marked, anodised (anodic coating not less than grade AC 10 as per IS : 1868 ) transparent or dyed to required colour or shade, with necessary screws etc. complete : 9.97.1 300x10 mm | J18: ='Measurement sheet'!I91 -> 2 | K18: ='Measurement sheet'!J91 -> Each | L18: ='Measurement sheet'!K91 -> 117.65 | M18: ='Measurement sheet'!L91 -> 235.3
A19: 16 | B19: 9.1 | C19: Providing and fixing aluminium handles, ISI marked, anodised (anodic coating not less than grade AC 10 as per IS : 1868) transparent or dyed to required colour or shade, with necessary screws etc. complete 9.100.1 125 mm | J19: ='Measurement sheet'!I93 -> 2 | K19: ='Measurement sheet'!J93 -> Each | L19: ='Measurement sheet'!K93 -> 60.05 | M19: ='Measurement sheet'!L93 -> 120.1
A20: 17 | B20: 9.119 | C20: Providing and fixing factory made P.V.C. door frame of size 50x47 mm with awall thickness of 5 mm, made out of extruded 5mm rigid PVC foam sheet, mitred at corners and joined with 2 Nos of 150 mm long brackets of 15x15 mm M.S. square tube, the vertical door frame profiles to be reinforced with 19x19 mm M.S. square tube of 19 gauge, EPDM rubber gasket weather seal to be provided through out the frame. The door frame to be fixed to the wall using M.S. screws of 65/100 mm size, complete as per manufacturer’s specification and direction of Engineerin- Charge. | J20: ='Measurement sheet'!I98 -> 69.3 | K20: ='Measurement sheet'!J98 -> R.M | L20: ='Measurement sheet'!K98 -> 408.25 | M20: ='Measurement sheet'!L98 -> 28291.73
A21: 18 | B21: 9.12 | C21: Providing and fixing factory made panel PVC door shutter consisting of frame made out of M.S. tubes of 19 gauge thickness and size of 19 mm x 19 mm for styles and 15x15 mm for top & bottom rails. M.S. frame shall have a coat of steel primers of approved make and manufacture.M.S. frame covered with 5 mm thick heat moulded PVC 'C' channel of size 30 mm thickness, 70 mm width out of which 50 mm shall be flat and 20 mm shall be tapered in 45 degree angle on both side forming styles and 5 mm thick, 95 mm wide PVC sheet out of which 75mm shall be flat and 20 mm shall be tapered in 45 degree on the inner side to form top and bottom rail and 115 mm wide PVC sheet out of which 75 mm shall be flat and 20 mm shall be tapered on both sides to form lock rail. Top, bottom and lock rails shall be provided both side of the panel. 10 mm (5 mm x 2 ) thick, 20 mm wide cross PVC sheet be provided as gap insert for top rail & bottom rail, paneling of 5 mm thick both side PVC sheet to be fitted in the M.S. frame welded/ sealed to the styles & rails with 7 mm (5 mm+2 mm) thick x 15 mm wide PVC sheet beading on inner side, and joined together with solvent cement adhesive. An additional 5 mm thick PVC strip of 20 mm width is to be stuck on the interior side of the 'C' Channel using PVC solvent adhesive etc. complete as per direction of Engineer-in-charge, manufacturer's specification & drawing. 9.120.1 30 mm thick plain PVC door shutters | J21: ='Measurement sheet'!I103 -> 22.05 | K21: ='Measurement sheet'!J103 -> Sqm | L21: ='Measurement sheet'!K103 -> 2455.1 | M21: ='Measurement sheet'!L103 -> 54134.96
A22: 19 | B22: 10.16 | C22: Steel work in built up tubular (round, square or rectangular hollow tubes etc.) trusses etc., including cutting, hoisting, fixing in position and applying a priming coat of approved steel primer, including welding and bolted with special shaped washers etc. complete. 10.16.2 Hot finished seamless type tubes (60x60x3.2) | J22: ='Measurement sheet'!I108 -> 281 | K22: ='Measurement sheet'!J108 -> Kg | L22: ='Measurement sheet'!K108 -> 168.95 | M22: ='Measurement sheet'!L108 -> 47474.95
A23: 20 | B23: 12.1 | C23: Providing corrugated G.S. sheet roofing including vertical / curved surface fixed with polymer coated J or L hooks, bolts and nuts 8 mm diameter with bitumen and G.I. limpet washers or with G.I. limpet washers filled with white lead, including a coat of approved steel primer and two coats of approved paint on overlapping of sheets complete (up to any pitch in horizontal/ vertical or curved surfaces), excluding the cost of purlins, rafters and trusses and including cutting to size and shape wherever required. 12.1.2 0.80 mm thick with zinc coating not less than 275 gm/m² | J23: ='Measurement sheet'!I112 -> 237.2 | K23: ='Measurement sheet'!J112 -> Sqm | L23: ='Measurement sheet'!K112 -> 1135.45 | M23: ='Measurement sheet'!L112 -> 269328.74
A24: 21 | B24: 12.4 | C24: Providing ridges or hips of width 60 cm overall width plain G.S. sheet fixed with polymer coated J or L hooks, bolts and nuts 8 mm dia G.I. limpet and bitumen washers complete. 12.4.1 0.80 mm thick with zinc coating not less than 275 gm/m² | J24: ='Measurement sheet'!I114 -> 20.5 | K24: ='Measurement sheet'!J114 -> Mtr | L24: ='Measurement sheet'!K114 -> 822.15 | M24: ='Measurement sheet'!L114 -> 16854.08
A25: 22 | B25: 12.52 | C25: Providing and fixing tiled false ceiling of specified materials of size 595x595 mm in true horizontal level, suspended on inter locking metal grid of hot dipped galvanized steel sections ( galvanized @ 120 grams/ sqm, both side inclusive) consisting of main "T" runner with suitably spaced joints to get required length and of size 24x38 mm made from 0.30 mm thick (minimum) sheet, spaced at 1200 mm center to center and cross "T" of size 24x25 mm made of 0.30 mm thick (minimum) sheet, 1200 mm long spaced between main "T" at 600 mm center to center to form a grid of 1200x600 mm and secondary cross "T" of length 600 mm and size 24x25 mm made of 0.30 mm thick (minimum) sheet to be interlocked at middle of the 1200x600 mm panel to form grids of 600x600 mm and wall angle of size 24x24x0.3 mm and laying false ceiling tiles of approved texture in the grid including, required cutting/making, opening for services like diffusers, grills, light fittings, fixtures, smoke detectors etc. Main"T" runners to be suspended from ceiling using GI slotted cleats ofsize 27 x 37 x 25 x1.6 mm fixed to ceiling with 12.5 mm dia and 50mm long dash fasteners, 4 mm GI adjustable rods with galvanisedbutterfly level clips of size 85 x 30 x 0.8 mm spaced at 1200 mmcenter to center along main T, bottom exposed width of 24 mm of allT-sections shall be pre-painted with polyester paint, all complete forall heights as per specifications, drawings and as rected byEngineer-in-charge. 12.52.3 12.5 mm thick square edge PVC Laminated Gypsum Tile of size 595x595 mm, made of Gypsum plasterboard, manufactured from natural gypsum as per IS 2095 part I and laminated with white 0.16mm thick fire retardant PVC film on the face side and 12micron metalized polyester on the back side with all edges sealed with | J25: ='Measurement sheet'!I123 -> 146.92 | K25: ='Measurement sheet'!J123 -> Sqm | L25: ='Measurement sheet'!K123 -> 1948.95 | M25: ='Measurement sheet'!L123 -> 286339.73
A26: 23 | B26: 17.3 | C26: Providing and fixing white vitreous china pedestal type water closet (European type) with seat and lid, 10 litre low level white vitreous china flushing cistern & C.P. flush bend with fittings & C.I. brackets, 40 mm flush bend, overflow arrangement with specials of standard make and mosquito proof coupling of approved municipal design complete, including painting of fittings and brackets, cutting and making good the walls and floors wherever required : 17.3.1 W.C. pan with ISI marked white solid plastic seat and lid | J26: ='Measurement sheet'!I125 -> 8 | K26: ='Measurement sheet'!J125 -> each | L26: ='Measurement sheet'!K125 -> 6941.3 | M26: ='Measurement sheet'!L125 -> 55530.4
A27: 24 | B27: 17.7(A) | C27: Providing and fixing wash basin with C.I. brackets, 15 mm dia CP Brass single hole basin mixer of approved quality and make, including painting of fittings and brackets, cutting and making good the walls wherever required: (a) White Vitreous China Wash basin size 550x400 mm with a 15 mm CP Brass single hole basin mixer | J27: ='Measurement sheet'!I127 -> 11 | K27: ='Measurement sheet'!J127 -> each | L27: ='Measurement sheet'!K127 -> 4542.4 | M27: ='Measurement sheet'!L127 -> 49966.4
A28: 25 | B28: 17.22B | C28: Providing and fixing CP Brass Single lever telephonic wall mixer of quality & make as approved by Engineer in charge. (a) 15 mm nominal dia | J28: ='Measurement sheet'!I129 -> 8 | K28: ='Measurement sheet'!J129 -> each | L28: ='Measurement sheet'!K129 -> 6119.15 | M28: ='Measurement sheet'!L129 -> 48953.2
A29: 26 | B29: 17.31 | C29: Providing and fixing 600x450 mm beveled edge mirror of superior glass (of approved quality) complete with 6 mm thick hard board ground fixed to wooden cleats with C.P. brass screws and washers complete. | J29: ='Measurement sheet'!I131 -> 10 | K29: ='Measurement sheet'!J131 -> each | L29: ='Measurement sheet'!K131 -> 1411.15 | M29: ='Measurement sheet'!L131 -> 14111.5
A30: 27 | B30: 17.16A | C30: Providing and fixing 8 mm dia C.P. / S.S. Jet with flexible tube upto 1 metre long with S.S. triangular plate to Eureopean type W.C. of quality and make as approved by Engineer - in - charge. | J30: ='Measurement sheet'!I133 -> 8 | K30: ='Measurement sheet'!J133 -> each | L30: ='Measurement sheet'!K133 -> 299.35 | M30: ='Measurement sheet'!L133 -> 2394.8
A31: 28 | B31: 18.49 | C31: Providing and fixing C.P. brass bib cock of approved quality conforming to IS:8931 : 18.49.1 15 mm nominal bore | J31: ='Measurement sheet'!I135 -> 12 | K31: ='Measurement sheet'!J135 -> each | L31: ='Measurement sheet'!K135 -> 434.2 | M31: ='Measurement sheet'!L135 -> 5210.4
A32: 29 | B32: 17.71 | C32: Providing and fixing PTMT liquid soap container 109 mm wide, 125 mm high and 112 mm distance from wall of standard shape with bracket of the same materials with snap fittings of approved quality and colour, weighing not less than 105 gms. | J32: ='Measurement sheet'!I137 -> 8 | K32: ='Measurement sheet'!J137 -> each | L32: ='Measurement sheet'!K137 -> 146.3 | M32: ='Measurement sheet'!L137 -> 1170.4
A33: 30 | C33: Out side kitchen A-type (Plinth Area Rate) Total Plinth Area of the kitchen | J33: ='Measurement sheet'!I140 -> 16 | K33: ='Measurement sheet'!J140 -> Sqm | L33: ='Measurement sheet'!K140 -> 17200 | M33: ='Measurement sheet'!L140 -> 275200
A34: 31 | B34: 16.78 | C34: Construction of granular sub-base by providing close graded Material conforming to specifications, mixing in a mechanical mix plant at OMC, carriage of mixed material by tippers to work site, for all leads & lifts, spreading in uniform layers of specified thickness with motor grader on prepared surface and compacting with vibratory power roller to achieve the desired density, complete as per specifications and directions of Engineer-in-Charge. 16.78.1 With material conforming to Grade-I (size range 75 mm to 0.075 mm) having CBR Value-30 | J34: ='Measurement sheet'!I142 -> 28.9 | K34: ='Measurement sheet'!J142 -> Cum | L34: ='Measurement sheet'!K142 -> 2658.1 | M34: ='Measurement sheet'!L142 -> 76819.09
A35: 32 | B35: 16.68 | C35: Providing and laying 60mm thick faciory made cement concrete interlocking paver block of M -30 grade made by block making machine with strong vibratory compaction, of approved size, design & shape, laid in required colour and pattern over and including 50mm thick compacted bed of coarse sand, filling the joints with line sand etc. all complete as per the direction of Engineer-in-charge. | J35: ='Measurement sheet'!I144 -> 289 | K35: ='Measurement sheet'!J144 -> Sqm | L35: ='Measurement sheet'!K144 -> 951 | M35: ='Measurement sheet'!L144 -> 274839
A36: 33 | C36: Any other unseen item of work from DSR 2021-22 that may occur during execution of the work. | M36: 20100
A37: Total = | M37: =ROUND(SUM(M4:M36),0) -> 2297170
C39: (Rupees twenty two lakh ninety seven thousand one hundred seventy) only

Sheet Abst
A1: Name of work : Renovation & Repair of Circuit House at Bokakhat Co District.
A2: Abstract of Cost
A3: Sl No. | B3: Description | H3: Amount
A4: 1 | B4: Civil works (A) = | H4: =+'BOQ1'!M37 -> 2297170
A5: 2 | B5: Electrical works (B) = | H5: =+Electrical!G29 -> 521703
A6: 3 | B6: Modular Kitchen = | H6: 559950
A7: 4 | B7: Total = | H7: =SUM(H4:H6) -> 3378823
A8: 5 | B8: Added contingencies 5% = | H8: =H7*5% -> 168941.15 | M8: 2297171.5
A9: 6 | B9: Grand Total = | H9: =H8+H7 -> 3547764.1
A10: 7 | B10: Say (Round off) = | H10: =ROUND(H9,-1) -> 3547760
A11: (Rupees thirty five lakh forty seven thousand seven hundred sixty) only
M12: 15000000
M13: =M12-H10 -> 11452240
A15: Asstt. Executive Engineer, PW (B&NH)D Bokakhat & Dergaon Territorial Building Sub- Division, Bokakhat | E15: Executive Engineer, PW (B&NH)D Golaghat District Territorial Building Division, Golaghat

Sheet Electrical
A1: Name of work:- Renovation & Repair of Circuit House at Bokakhat Co District.
A2: Electrical works (B)
A3: SL NO. | B3: ITEM. | C3: Description of materials | D3: UNIT | E3: RATE | F3: QNTY. | G3: AMOUNT
A4: 1 | B4: 1.10 | C4: Wiring for light point/ fan point/ exhaust fan point/ call bell point with 1.5 sq.mm FRLS PVC insulated copper conductor single core cable in surface / recessed medium class PVC conduit, with modular switch, modular plate, suitable GI box and earthing the point with 1.5 sq.mm. FRLS PVC insulated copper conductor single core cable etc as required.
B5: 1.10.1 | C5: Group A | D5: Point | E5: 1015 | F5: 15 | G5: =E5*F5 -> 15225
A6: 2 | B6: 1.12 | C6: Wiring for light/ power plug with 2X4 sq. mm FRLS PVC insulated copper conductor single core cable in surface/ recessed medium class PVC conduit along with 1 No 4 sq. mm FRLS PVC insulated copper conductor single core cable for loop earthing as required. | D6: mtr | E6: 334 | F6: 180 | G6: =E6*F6 -> 60120
A7: 3 | B7: 1.14 | C7: Wiring for circuit/ submain wiring along with earth wire with the following sizes of FRLS PVC insulated copper conductor, single core cable in surface/ recessed medium class PVC conduit as required
B8: 1.14.2 | C8: 2 X 2.5 sq. mm + 1 X 2.5 sq. mm earth wire | D8: mtr | E8: 275 | F8: 150 | G8: =E8*F8 -> 41250
B9: 1.14.4 | C9: 2 X 6 sq. mm + 1 X 6 sq. mm earth wire | D9: mtr | E9: 439 | F9: 40 | G9: =E9*F9 -> 17560
A10: 4 | B10: 1.24 | C10: Supplying and fixing following modular switch/ socket on the existing modular plate & switch box including connections but excluding modular plate etc. as required.
B11: 1.24.1 | C11: 5/6 amps switch | D11: each | E11: 103 | F11: 4 | G11: =E11*F11 -> 412
B12: 1.24.3 | C12: 15/16 amp switch | D12: each | E12: 156 | F12: 12 | G12: =E12*F12 -> 1872
B13: 1.24.4 | C13: 3 pin 5/6 amp socket outlet | D13: each | E13: 122 | F13: 4 | G13: =E13*F13 -> 488
B14: 1.24.5 | C14: 6 pin 15/16 amp socket outlet | D14: each | E14: 197 | F14: 12 | G14: =E14*F14 -> 2364
A15: 5 | B15: 1.25 | C15: Supplying and fixing two module stepped type electronic fan regulator on the existing modular plate switch box including connections but excluding modular plate etc. as required. | D15: each | E15: 369 | F15: 4 | G15: =E15*F15 -> 1476
A16: 6 | B16: 1.27 | C16: Supplying and fixing following size/ modules, GI box along with modular base & cover plate for modular switches in recess etc as required.
B17: 1.27.1 | C17: 1 or 2 Module (75mmX75mm) | D17: each | E17: 298 | F17: 8 | G17: =E17*F17 -> 2384
B18: 1.27.3 | C18: 4 Module (125mmX75mm) | D18: each | E18: 343 | F18: 4 | G18: =E18*F18 -> 1372
B19: 1.27.6 | C19: 12 Module (200mmX150mm) | D19: each | E19: 547 | F19: 2 | G19: =E19*F19 -> 1094
A20: 7 | B20: 1.28 | C20: Supplying and fixing following Modular base & cover plate on existing modular metal boxes etc. as required.
B21: 1.28.1 | C21: 1 or 2 Module | D21: each | E21: 133 | F21: 8 | G21: =E21*F21 -> 1064
B22: 1.28.3 | C22: 4 Module | D22: each | E22: 158 | F22: 4 | G22: =E22*F22 -> 632
B23: 1.28.6 | C23: 12 Module | D23: each | E23: 272 | F23: 2 | G23: =E23*F23 -> 544
A24: 8 | B24: 1.44 | C24: Installation, testing and commissioning of ceiling fan, including wiring the down rods of standard length (upto 30 cm) with 1.5 sq. mm FRLS PVC insulated, copper conductor, single core cable etc. as required. | D24: Metre | E24: 171 | F24: 6 | G24: =E24*F24 -> 1026
A25: 9 | B25: 19.1 | C25: Supply ,installation ,testing and commissioning of 1200 mm sweep ,BEE 5 Star rated, ceiling fan with brushless direct curretnt(BLDC) Motor | D25: each | E25: 2730 | F25: 4 | G25: =E25*F25 -> 10920
A26: 10 | B26: A-1 | C26: Supplying fitting and fixing of Electric Storage Water Heater 10 L capacity.( Havells make -Puro Turbo Dx.item code-. GHWAPXTPI010) | D26: each | E26: 14794 | F26: 8 | G26: =E26*F26 -> 118352
A27: 11 | B27: A-2 | C27: Supplying with installation testing and commissioning of Hi -- wall 4 star rating non ducted split inverter type air conditioner of the following capacity with cordless remote complete with indoor and outdoor unit, copper pipe and electrical connection as approved by the Deptt.)up to 5 m between the room unit and out door unit as directed by the department.
C28: 1.5 T capacity Haier make | D28: each | E28: 60887 | F28: 4 | G28: =E28*F28 -> 243548
E29: Total | F29: Rs. | G29: =SUM(G5:G28) -> 521703
C30: (Rupees five lakh twenty one thousand sven hundred three)only

Sheet E. Statement
A2: Analysis of rate -- 1
B3: Supplying fitting and fixing of Electric Storage Water Heater 10 L capacity.( Havells make -Puro Turbo Dx.item code-. GHWAPXTPI010)
A4: ICD No | B4: Description | C4: Unit | D4: Qty | E4: Rate Rs. | F4: Amount (Rs.)
B5: MATERIALS
A6: A | B6: Electric Storage Water Heater 10 L capacity.( Havells make -Puro Turbo Dx) MRP @15350.00 discount @ 20 % | C6: each | D6: 1 | E6: =15350*0.8 -> 12280 | F6: =E6*D6 -> 12280
B7: Add Cartage @1 % | E7: Rs. | F7: =F6*0.01 -> 122.8
B8: Total A | E8: Rs. | F8: =F6+F7 -> 12402.8
A9: B | B9: Labour
A10: 1001 | B10: Wireman | C10: day | D10: 0.2 | E10: 806 | F10: =ROUND(D10*E10,2) -> 161.2
A11: 1007 | B11: Khallasi | C11: day | D11: 0.2 | E11: 663 | F11: =E11*D11 -> 132.6
B12: TOTAL | E12: Rs. | F12: =F10+F11 -> 293.8
B13: ='[1]Basic Material'!$T$3 -> Add 12% GST (MF = 0.1405) | E13: Rs. | F13: =F12*0.1405 -> 41.28
B14: TOTAL | E14: Rs. | F14: =F8+F12+F13 -> 12737.88
B15: OVERHEADS & PROFIT @ 15 % | D15: 0.15 | E15: Rs. | F15: =F14*0.15 -> 1910.68
B16: TOTAL | E16: Rs. | F16: =F14+F15 -> 14648.56
B17: Adding LWC 1% | D17: 0.01 | E17: Rs. | F17: =F16*D17 -> 146.49
B18: Total | E18: Rs. | F18: =F16+F17 -> 14795.05
B19: Say, | E19: Rs. | F19: =ROUND(F18,0) -> 14795
A22: Analysis of rate -- 2
B23: Supplying with installation testing and commissioning of Hi -- wall 4 star rating non ducted split inverter type air conditioner of the following capacity with cordless remote complete with indoor and outdoor unit, copper pipe and electrical connection as approved by the Deptt.)up to 5 m between the room unit and out door unit as directed by the department.
A24: ICD No | B24: Description | C24: Unit | D24: Qty | E24: Rate Rs. | F24: Amount (Rs.)
B25: MATERIALS
A26: A | B26: 1.5 T capacity Haier make .Series-Kinochi ,Model-HSU18K-PYG4B(INV) MRP @ 64670.00 discount @20% | C26: each | D26: 1 | E26: =64670*0.8 -> 51736 | F26: =E26*D26 -> 51736
B27: Add Cartage @1 % | E27: Rs. | F27: =F26*0.01 -> 517.36
B28: Total A | E28: Rs. | F28: =F26+F27 -> 52253.36
A29: B | B29: Labour
A30: 1001 | B30: Wireman | C30: day | D30: 0.1 | E30: 806 | F30: =ROUND(D30*E30,2) -> 80.6
A31: 1007 | B31: Khallasi | C31: day | D31: 0.1 | E31: 663 | F31: =E31*D31 -> 66.3
B32: TOTAL | E32: Rs. | F32: =F30+F31 -> 146.9
B33: ='[1]Basic Material'!$T$3 -> Add 12% GST (MF = 0.1405) | E33: Rs. | F33: =F32*0.1405 -> 20.64
B34: TOTAL | E34: Rs. | F34: =F28+F32+F33 -> 52420.9
B35: OVERHEADS & PROFIT @ 15 % | D35: 0.15 | E35: Rs. | F35: =F34*0.15 -> 7863.14
B36: TOTAL | E36: Rs. | F36: =F34+F35 -> 60284.04
B37: Adding LWC 1% | D37: 0.01 | E37: Rs. | F37: =F36*D37 -> 602.84
B38: Total | E38: Rs. | F38: =F36+F37 -> 60886.88
B39: Say, | E39: Rs. | F39: =ROUND(F38,0) -> 60887
