Workbook
Name \: #REF!
Name \0: #REF!
Name \a: #REF!
Name \b: #N/A
Name \C: #REF!
Name \l: #REF!
Name \m: #REF!
Name \n: #REF!
Name \p: #REF!
Name \r: #REF!
Name \s: #REF!
Name \v: #N/A
Name \w: #N/A
Name \x: #REF!
Name _: #REF!
Name ____________________________________________________b111121: #REF!
Name ____________________________________________________Ki1: #REF!
Name ____________________________________________________Ki2: #REF!
Name ____________________________________________________MAN1: #REF!
Name ____________________________________________________PB1: #REF!
Name ____________________________________________________TB2: #REF!
Name ___________________________________________________b111121: #REF!
Name ___________________________________________________Ki1: #REF!
Name ___________________________________________________Ki2: #REF!
Name ___________________________________________________MAN1: #REF!
Name ___________________________________________________PB1: #REF!
Name ___________________________________________________TB2: #REF!
Name __________________________________________________b111121: #REF!
Name __________________________________________________Ki1: #REF!
Name __________________________________________________Ki2: #REF!
Name __________________________________________________MAN1: #REF!
Name __________________________________________________PB1: #REF!
Name __________________________________________________TB2: #REF!
Name _________________________________________________b111121: #REF!
Name _________________________________________________Ki1: #REF!
Name _________________________________________________Ki2: #REF!
Name _________________________________________________MAN1: #REF!
Name _________________________________________________PB1: #REF!
Name _________________________________________________TB2: #REF!
Name ________________________________________________b111121: #REF!
Name ________________________________________________Ki1: #REF!
Name ________________________________________________Ki2: #REF!
Name ________________________________________________MAN1: #REF!
Name ________________________________________________PB1: #REF!
Name ________________________________________________TB2: #REF!
Name _______________________________________________b111121: #REF!
Name _______________________________________________Ki1: #REF!
Name _______________________________________________Ki2: #REF!
Name _______________________________________________MAN1: #REF!
Name _______________________________________________PB1: #REF!
Name _______________________________________________TB2: #REF!
Name ______________________________________________b111121: #REF!
Name ______________________________________________Ki1: #REF!
Name ______________________________________________Ki2: #REF!
Name ______________________________________________MAN1: #REF!
Name ______________________________________________PB1: #REF!
Name ______________________________________________TB2: #REF!
Name _____________________________________________b111121: #REF!
Name _____________________________________________Ki1: #REF!
Name _____________________________________________Ki2: #REF!

Sheet Cover
A2: GOVT OF ASSAM
A13: PUBLIC WORKS DEPARTMENT
A14: (BUILDING WINGS)
B16: Name of Work | E16: :- | F16: =Report!D3 -> Repairing and Renovation of Circuit House at Bokakhat Co District under Golaghat District
B19: Name of Circle | E19: :- | F19: Jorhat Building Circle, Jorhat
B20: Name of Division | E20: :- | F20: PW(B&NH)D, Golaghat District Territorial Building Division, Golaghat.
B21: Name of Sub- Division | E21: :- | F21: PW(B&NH)D, Bokakhat & Dergaon Territorial Building Sub-Division, Bokakhat.
B24: Estimated Amount | E24: :- | F24: =Report!D7 -> 4623500
B26: =Report!D8 -> (Rupees forty eight lakh twenty three thousand five hundred ) only.

Sheet Report
A1: GOVERNMENT OF ASSAM PUBLIC WORKS DEPARTMENT (BUILDING WINGS)
A3: Name of Work | C3: : | D3: Repairing and Renovation of Circuit House at Bokakhat Co District under Golaghat District
A4: Name of Circle : | C4: : | D4: Jorhat Building Circle, Jorhat
A5: Name of Division:- | C5: : | D5: PW(B&NH)D, Golaghat District Territorial Building Division, Golaghat.
A6: Name of Sub-Division:- | C6: : | D6: PW(B&NH)D, Bokakhat & Dergaon Territorial Building Sub- Division, Bokakhat
A7: Estimated Amount | C7: : | D7: =Abstract!G20 -> 4623500
D8: =Abstract!B22 -> (Rupees forty eight lakh twenty three thousand five hundred ) only.
A11: This estimate has been prepared to show the probable cost for construction of the above noted work.
A13: R E P O R T
A15: =" The estimate amounting to Rs. "&TEXT(D7,"#,##0.00")&" "&D8&" "&"has been prepared to show the probable cost for work for """&D3&"""" & "This estimate is prepared as per letter received from Co-District Commissioner, Bokakhat vide No- BNZ.5/2026/, dtd 09/09/2026." -> The estimate amounting to Rs. 46,23,500.00 (Rupees forty eight lakh twenty three thousand five hundred ) only. has been prepared to show the probable cost for work for "Repairing and Renovation of Circuit House at Bokakhat Co District under Golaghat District"This estimate is prepared as per letter received from Co-District Commissioner, Bokakhat vide No- BNZ.5/2026/, dtd 09/09/2026.
A16: Location :
B17: Circuit House, Bokakhat.
A19: Necessity: The Circuit House, Bokakhat is an important Government accommodation facility used for the stay of Government officers, dignitaries, visiting officials and other authorised guests during their official visits to Bokakhat and adjoining areas. The existing building requires necessary repair and renovation to improve its safety, functionality and overall conditions. Accordingly, this estimate has been prepared for proper functioning of the building.
A23: Provisions:
A24: This estimate contains the following provisions:-
A25: 1 Repairing and Renovation of Circuit House RCC G+1 First Floor A/Type Residential Building, Kitchen , Dormitory and Cottage (Guest Room
A26: 2 Sanitary and Water Supply Fitting works
A27: 3 Electrical Works.
A28: 4 Installation of Solar Street Lights.
A29: This estimate is based on CPWD Plinth area Rate 2021 and CPWD schedule of Rate (Building) DSR Vol. 1 & Vol. 2 for the year 2021 and E & M (for Electrical) for the year 2022. The provision for Contingencies @5%, Premium is also considered as per norms. All works will be carried out as per PWD general specifications current in the state and as per IS code of practice.

Sheet Abstract
B3: ='AType Cottage'!A1 -> Name of Work :- Repairing and Renovation of Circuit House at Bokakhat Co District under Golaghat District
B5: ABSTRACT OF COST
B7: PARTICULARS | G7: Estimated Amount
B8: 1. Repairing and Renovation Works….................. | F8: = | G8: ='Rennovation BOQ'!M40 -> 2357162
B9: 2. Sanitary and Water Supply Fittings…................ | F9: = | G9: ='Sanitart Works'!N40 -> 498118
B10: 3. Cost of Electrification Works.………………… | F10: = | G10: =[50]Electrical!$G$31 -> 720512
B11: 4. Installation of Solar Street lights…............................. | F11: = | G11: =[51]est!$G$6 -> 162192
B12: Total (A) | F12: = | G12: =SUM(G8:G11) -> 3737984
B13: Add 6.33% GST | F13: = | G13: =ROUND(6.33%*G12,0) -> 236614
B14: Total (B) | F14: = | G14: =SUM(G12:G13) -> 3974598 | H14: =G14/G20 -> 0.85965135
B15: Quotation Items:
B16: 1. Furniture…....................................................... | F16: = | G16: =furniture!F12 -> 428772
B17: Total (C) | F17: = | G17: =SUM(G14:G16) -> 4403370 | H17: =#REF!+G16 -> #REF! | I17: =H17/G20 -> #REF!
B18: Add Contigency 5% | F18: = | G18: =ROUND(5%*G17,0) -> 220169
B19: Grand Total | F19: = | G19: =SUM(G17:G18) -> 4623539 | H19: 4898500
B20: SAY | F20: = | G20: =ROUND(G19,-2) -> 4623500
B22: =CU39 -> (Rupees forty eight lakh twenty three thousand five hundred ) only.
A39: =G20 -> 4623500 | B39: COPY CELLS=> | C39: 1 | D39: one | E39: 2 | F39: two | G39: 3 | H39: three | I39: 4 | J39: four | K39: 5 | L39: five | M39: 6 | N39: six | O39: 7 | P39: seven | Q39: 8 | R39: eight | S39: 9 | T39: nine | U39: 10 | V39: ten | W39: 11 | X39: eleven | Y39: 12 | Z39: twelve | AA39: 13 | AB39: thirteen | AC39: 14 | AD39: fourteen | AE39: 15 | AF39: fifteen | AG39: 16 | AH39: sixteen | AI39: 17 | AJ39: seventeen | AK39: 18 | AL39: eighteen | AM39: 19 | AN39: nineteen | AO39: <=COPY CELLS | AP39: WORDS-> | AQ39: CRORE | AR39: =IF(AX39="","",IF(AX39>=90,"ninety "&IF((AX39-ROUNDDOWN(AX39,-1))=C39,D39,"")&IF((AX39-ROUNDDOWN(AX39,-1))=E39,F39,"")&IF((AX39-ROUNDDOWN(AX39,-1))=G39,H39,"")&IF((AX39-ROUNDDOWN(AX39,-1))=I39,J39,"")&IF((AX39-ROUNDDOWN(AX39,-1))=K39,L39,"")&IF((AX39-ROUNDDOWN(AX39,-1))=M39,N39,"")&IF((AX39-ROUNDDOWN(AX39,-1))=O39,P39,"")&IF((AX39-ROUNDDOWN(AX39,-1))=Q39,R39,"")&IF((AX39-ROUNDDOWN(AX39,-1))=S39,T39,""),IF(AX39>=80,"eighty "&IF((AX39-ROUNDDOWN(AX39,-1))=1,D39,"")&IF((AX39-ROUNDDOWN(AX39,-1))=2,F39,"")&IF((AX39-ROUNDDOWN(AX39,-1))=G39,H39,"")&IF((AX39-ROUNDDOWN(AX39,-1))=I39,J39,"")&IF((AX39-ROUNDDOWN(AX39,-1))=K39,L39,"")&IF((AX39-ROUNDDOWN(AX39,-1))=M39,N39,"")&IF((AX39-ROUNDDOWN(AX39,-1))=O39,P39,"")&IF((AX39-ROUNDDOWN(AX39,-1))=Q39,R39,"")&IF((AX39-ROUNDDOWN(AX39,-1))=S39,T39,""),""))) | AS39: =IF(AX39="","",IF(AX39>79,"",IF(AX39>=70,"seventy "&IF((AX39-ROUNDDOWN(AX39,-1))=C39,D39,"")&IF((AX39-ROUNDDOWN(AX39,-1))=E39,F39,"")&IF((AX39-ROUNDDOWN(AX39,-1))=G39,H39,"")&IF((AX39-ROUNDDOWN(AX39,-1))=I39,J39,"")&IF((AX39-ROUNDDOWN(AX39,-1))=K39,L39,"")&IF((AX39-ROUNDDOWN(AX39,-1))=M39,N39,"")&IF((AX39-ROUNDDOWN(AX39,-1))=O39,P39,"")&IF((AX39-ROUNDDOWN(AX39,-1))=Q39,R39,"")&IF((AX39-ROUNDDOWN(AX39,-1))=S39,T39,""),IF(AX39>=60,"sixty "&IF((AX39-ROUNDDOWN(AX39,-1))=1,D39,"")&IF((AX39-ROUNDDOWN(AX39,-1))=2,F39,"")&IF((AX39-ROUNDDOWN(AX39,-1))=G39,H39,"")&IF((AX39-ROUNDDOWN(AX39,-1))=I39,J39,"")&IF((AX39-ROUNDDOWN(AX39,-1))=K39,L39,"")&IF((AX39-ROUNDDOWN(AX39,-1))=M39,N39,"")&IF((AX39-ROUNDDOWN(AX39,-1))=O39,P39,"")&IF((AX39-ROUNDDOWN(AX39,-1))=Q39,R39,"")&IF((AX39-ROUNDDOWN(AX39,-1))=S39,T39,""),"")))) | AT39: =IF(AX39="","",IF(AX39>59,"",IF(AX39>=50,"fifty "&IF((AX39-ROUNDDOWN(AX39,-1))=C39,D39,"")&IF((AX39-ROUNDDOWN(AX39,-1))=E39,F39,"")&IF((AX39-ROUNDDOWN(AX39,-1))=G39,H39,"")&IF((AX39-ROUNDDOWN(AX39,-1))=I39,J39,"")&IF((AX39-ROUNDDOWN(AX39,-1))=K39,L39,"")&IF((AX39-ROUNDDOWN(AX39,-1))=M39,N39,"")&IF((AX39-ROUNDDOWN(AX39,-1))=O39,P39,"")&IF((AX39-ROUNDDOWN(AX39,-1))=Q39,R39,"")&IF((AX39-ROUNDDOWN(AX39,-1))=S39,T39,""),IF(AX39>=40,"forty "&IF((AX39-ROUNDDOWN(AX39,-1))=1,D39,"")&IF((AX39-ROUNDDOWN(AX39,-1))=2,F39,"")&IF((AX39-ROUNDDOWN(AX39,-1))=G39,H39,"")&IF((AX39-ROUNDDOWN(AX39,-1))=I39,J39,"")&IF((AX39-ROUNDDOWN(AX39,-1))=K39,L39,"")&IF((AX39-ROUNDDOWN(AX39,-1))=M39,N39,"")&IF((AX39-ROUNDDOWN(AX39,-1))=O39,P39,"")&IF((AX39-ROUNDDOWN(AX39,-1))=Q39,R39,"")&IF((AX39-ROUNDDOWN(AX39,-1))=S39,T39,""),"")))) | AU39: =IF(AX39="","",IF(AX39>39,"",IF(AX39>=30,"thirty "&IF((AX39-ROUNDDOWN(AX39,-1))=C39,D39,"")&IF((AX39-ROUNDDOWN(AX39,-1))=E39,F39,"")&IF((AX39-ROUNDDOWN(AX39,-1))=G39,H39,"")&IF((AX39-ROUNDDOWN(AX39,-1))=I39,J39,"")&IF((AX39-ROUNDDOWN(AX39,-1))=K39,L39,"")&IF((AX39-ROUNDDOWN(AX39,-1))=M39,N39,"")&IF((AX39-ROUNDDOWN(AX39,-1))=O39,P39,"")&IF((AX39-ROUNDDOWN(AX39,-1))=Q39,R39,"")&IF((AX39-ROUNDDOWN(AX39,-1))=S39,T39,""),IF(AX39>=20,"twenty "&IF((AX39-ROUNDDOWN(AX39,-1))=1,D39,"")&IF((AX39-ROUNDDOWN(AX39,-1))=2,F39,"")&IF((AX39-ROUNDDOWN(AX39,-1))=G39,H39,"")&IF((AX39-ROUNDDOWN(AX39,-1))=I39,J39,"")&IF((AX39-ROUNDDOWN(AX39,-1))=K39,L39,"")&IF((AX39-ROUNDDOWN(AX39,-1))=M39,N39,"")&IF((AX39-ROUNDDOWN(AX39,-1))=O39,P39,"")&IF((AX39-ROUNDDOWN(AX39,-1))=Q39,R39,"")&IF((AX39-ROUNDDOWN(AX39,-1))=S39,T39,""),"")))) | AV39: =IF(AX39="","",IF(AX39=C39,D39,"")&IF(AX39=E39,F39,"")&IF(AX39=G39,H39,"")&IF(AX39=I39,J39,"")&IF(AX39=K39,L39,"")&IF(AX39=M39,N39,"")&IF(AX39=O39,P39,"")&IF(AX39=Q39,R39,"")&IF(AX39=S39,T39,"")&IF(AX39=U39,V39,"")&IF(AX39=W39,X39,"")&IF(AX39=Y39,Z39,"")&IF(AX39=AA39,AB39,"")&IF(AX39=AC39,AD39,"")&IF(AX39=AE39,AF39,"")&IF(AX39=AG39,AH39,"")&IF(AX39=AI39,AJ39,"")&IF(AX39=AK39,AL39,"")&IF(AX39=AM39,AN39,"")) | AX39: =IF(A39>=10000000,ROUNDDOWN(A39,-7)/10000000,"") | AY39: =IF(AR39="","",AR39)&IF(AS39="","",AS39)&IF(AT39="","",AT39)&IF(AU39="","",AU39)&IF(AV39="","",AV39) | AZ39: LAKH | BA39: =IF(BG39="","",IF(BG39>=90,"ninety "&IF((BG39-ROUNDDOWN(BG39,-1))=C39,D39,"")&IF((BG39-ROUNDDOWN(BG39,-1))=E39,F39,"")&IF((BG39-ROUNDDOWN(BG39,-1))=G39,H39,"")&IF((BG39-ROUNDDOWN(BG39,-1))=I39,J39,"")&IF((BG39-ROUNDDOWN(BG39,-1))=K39,L39,"")&IF((BG39-ROUNDDOWN(BG39,-1))=M39,N39,"")&IF((BG39-ROUNDDOWN(BG39,-1))=O39,P39,"")&IF((BG39-ROUNDDOWN(BG39,-1))=Q39,R39,"")&IF((BG39-ROUNDDOWN(BG39,-1))=S39,T39,""),IF(BG39>=80,"eighty "&IF((BG39-ROUNDDOWN(BG39,-1))=1,D39,"")&IF((BG39-ROUNDDOWN(BG39,-1))=2,F39,"")&IF((BG39-ROUNDDOWN(BG39,-1))=G39,H39,"")&IF((BG39-ROUNDDOWN(BG39,-1))=I39,J39,"")&IF((BG39-ROUNDDOWN(BG39,-1))=K39,L39,"")&IF((BG39-ROUNDDOWN(BG39,-1))=M39,N39,"")&IF((BG39-ROUNDDOWN(BG39,-1))=O39,P39,"")&IF((BG39-ROUNDDOWN(BG39,-1))=Q39,R39,"")&IF((BG39-ROUNDDOWN(BG39,-1))=S39,T39,""),""))) | BB39: =IF(BG39="","",IF(BG39>79,"",IF(BG39>=70,"seventy "&IF((BG39-ROUNDDOWN(BG39,-1))=C39,D39,"")&IF((BG39-ROUNDDOWN(BG39,-1))=E39,F39,"")&IF((BG39-ROUNDDOWN(BG39,-1))=G39,H39,"")&IF((BG39-ROUNDDOWN(BG39,-1))=I39,J39,"")&IF((BG39-ROUNDDOWN(BG39,-1))=K39,L39,"")&IF((BG39-ROUNDDOWN(BG39,-1))=M39,N39,"")&IF((BG39-ROUNDDOWN(BG39,-1))=O39,P39,"")&IF((BG39-ROUNDDOWN(BG39,-1))=Q39,R39,"")&IF((BG39-ROUNDDOWN(BG39,-1))=S39,T39,""),IF(BG39>=60,"sixty "&IF((BG39-ROUNDDOWN(BG39,-1))=1,D39,"")&IF((BG39-ROUNDDOWN(BG39,-1))=2,F39,"")&IF((BG39-ROUNDDOWN(BG39,-1))=G39,H39,"")&IF((BG39-ROUNDDOWN(BG39,-1))=I39,J39,"")&IF((BG39-ROUNDDOWN(BG39,-1))=K39,L39,"")&IF((BG39-ROUNDDOWN(BG39,-1))=M39,N39,"")&IF((BG39-ROUNDDOWN(BG39,-1))=O39,P39,"")&IF((BG39-ROUNDDOWN(BG39,-1))=Q39,R39,"")&IF((BG39-ROUNDDOWN(BG39,-1))=S39,T39,""),"")))) | BC39: =IF(BG39="","",IF(BG39>59,"",IF(BG39>=50,"fifty "&IF((BG39-ROUNDDOWN(BG39,-1))=C39,D39,"")&IF((BG39-ROUNDDOWN(BG39,-1))=E39,F39,"")&IF((BG39-ROUNDDOWN(BG39,-1))=G39,H39,"")&IF((BG39-ROUNDDOWN(BG39,-1))=I39,J39,"")&IF((BG39-ROUNDDOWN(BG39,-1))=K39,L39,"")&IF((BG39-ROUNDDOWN(BG39,-1))=M39,N39,"")&IF((BG39-ROUNDDOWN(BG39,-1))=O39,P39,"")&IF((BG39-ROUNDDOWN(BG39,-1))=Q39,R39,"")&IF((BG39-ROUNDDOWN(BG39,-1))=S39,T39,""),IF(BG39>=40,"forty "&IF((BG39-ROUNDDOWN(BG39,-1))=1,D39,"")&IF((BG39-ROUNDDOWN(BG39,-1))=2,F39,"")&IF((BG39-ROUNDDOWN(BG39,-1))=G39,H39,"")&IF((BG39-ROUNDDOWN(BG39,-1))=I39,J39,"")&IF((BG39-ROUNDDOWN(BG39,-1))=K39,L39,"")&IF((BG39-ROUNDDOWN(BG39,-1))=M39,N39,"")&IF((BG39-ROUNDDOWN(BG39,-1))=O39,P39,"")&IF((BG39-ROUNDDOWN(BG39,-1))=Q39,R39,"")&IF((BG39-ROUNDDOWN(BG39,-1))=S39,T39,""),"")))) -> forty eight | BD39: =IF(BG39="","",IF(BG39>39,"",IF(BG39>=30,"thirty "&IF((BG39-ROUNDDOWN(BG39,-1))=C39,D39,"")&IF((BG39-ROUNDDOWN(BG39,-1))=E39,F39,"")&IF((BG39-ROUNDDOWN(BG39,-1))=G39,H39,"")&IF((BG39-ROUNDDOWN(BG39,-1))=I39,J39,"")&IF((BG39-ROUNDDOWN(BG39,-1))=K39,L39,"")&IF((BG39-ROUNDDOWN(BG39,-1))=M39,N39,"")&IF((BG39-ROUNDDOWN(BG39,-1))=O39,P39,"")&IF((BG39-ROUNDDOWN(BG39,-1))=Q39,R39,"")&IF((BG39-ROUNDDOWN(BG39,-1))=S39,T39,""),IF(BG39>=20,"twenty "&IF((BG39-ROUNDDOWN(BG39,-1))=1,D39,"")&IF((BG39-ROUNDDOWN(BG39,-1))=2,F39,"")&IF((BG39-ROUNDDOWN(BG39,-1))=G39,H39,"")&IF((BG39-ROUNDDOWN(BG39,-1))=I39,J39,"")&IF((BG39-ROUNDDOWN(BG39,-1))=K39,L39,"")&IF((BG39-ROUNDDOWN(BG39,-1))=M39,N39,"")&IF((BG39-ROUNDDOWN(BG39,-1))=O39,P39,"")&IF((BG39-ROUNDDOWN(BG39,-1))=Q39,R39,"")&IF((BG39-ROUNDDOWN(BG39,-1))=S39,T39,""),"")))) | BE39: =IF(BG39="","",IF(BG39=C39,D39,"")&IF(BG39=E39,F39,"")&IF(BG39=G39,H39,"")&IF(BG39=I39,J39,"")&IF(BG39=K39,L39,"")&IF(BG39=M39,N39,"")&IF(BG39=O39,P39,"")&IF(BG39=Q39,R39,"")&IF(BG39=S39,T39,"")&IF(BG39=U39,V39,"")&IF(BG39=W39,X39,"")&IF(BG39=Y39,Z39,"")&IF(BG39=AA39,AB39,"")&IF(BG39=AC39,AD39,"")&IF(BG39=AE39,AF39,"")&IF(BG39=AG39,AH39,"")&IF(BG39=AI39,AJ39,"")&IF(BG39=AK39,AL39,"")&IF(BG39=AM39,AN39,"")) | BG39: 48 | BH39: =IF(BA39="","",BA39)&IF(BB39="","",BB39)&IF(BC39="","",BC39)&IF(BD39="","",BD39)&IF(BE39="","",BE39) -> forty eight | BI39: THOUSAND | BJ39: =IF(BP39="","",IF(BP39>=90,"ninety "&IF((BP39-ROUNDDOWN(BP39,-1))=1,D39,"")&IF((BP39-ROUNDDOWN(BP39,-1))=2,F39,"")&IF((BP39-ROUNDDOWN(BP39,-1))=G39,H39,"")&IF((BP39-ROUNDDOWN(BP39,-1))=I39,J39,"")&IF((BP39-ROUNDDOWN(BP39,-1))=K39,L39,"")&IF((BP39-ROUNDDOWN(BP39,-1))=M39,N39,"")&IF((BP39-ROUNDDOWN(BP39,-1))=O39,P39,"")&IF((BP39-ROUNDDOWN(BP39,-1))=Q39,R39,"")&IF((BP39-ROUNDDOWN(BP39,-1))=S39,T39,""),IF(BP39>=80,"eighty "&IF((BP39-ROUNDDOWN(BP39,-1))=1,D39,"")&IF((BP39-ROUNDDOWN(BP39,-1))=2,F39,"")&IF((BP39-ROUNDDOWN(BP39,-1))=G39,H39,"")&IF((BP39-ROUNDDOWN(BP39,-1))=I39,J39,"")&IF((BP39-ROUNDDOWN(BP39,-1))=K39,L39,"")&IF((BP39-ROUNDDOWN(BP39,-1))=M39,N39,"")&IF((BP39-ROUNDDOWN(BP39,-1))=O39,P39,"")&IF((BP39-ROUNDDOWN(BP39,-1))=Q39,R39,"")&IF((BP39-ROUNDDOWN(BP39,-1))=S39,T39,""),""))) | BK39: =IF(BP39="","",IF(BP39>79,"",IF(BP39>=70,"seventy "&IF((BP39-ROUNDDOWN(BP39,-1))=1,D39,"")&IF((BP39-ROUNDDOWN(BP39,-1))=2,F39,"")&IF((BP39-ROUNDDOWN(BP39,-1))=G39,H39,"")&IF((BP39-ROUNDDOWN(BP39,-1))=I39,J39,"")&IF((BP39-ROUNDDOWN(BP39,-1))=K39,L39,"")&IF((BP39-ROUNDDOWN(BP39,-1))=M39,N39,"")&IF((BP39-ROUNDDOWN(BP39,-1))=O39,P39,"")&IF((BP39-ROUNDDOWN(BP39,-1))=Q39,R39,"")&IF((BP39-ROUNDDOWN(BP39,-1))=S39,T39,""),IF(BP39>=60,"sixty "&IF((BP39-ROUNDDOWN(BP39,-1))=1,D39,"")&IF((BP39-ROUNDDOWN(BP39,-1))=2,F39,"")&IF((BP39-ROUNDDOWN(BP39,-1))=G39,H39,"")&IF((BP39-ROUNDDOWN(BP39,-1))=I39,J39,"")&IF((BP39-ROUNDDOWN(BP39,-1))=K39,L39,"")&IF((BP39-ROUNDDOWN(BP39,-1))=M39,N39,"")&IF((BP39-ROUNDDOWN(BP39,-1))=O39,P39,"")&IF((BP39-ROUNDDOWN(BP39,-1))=Q39,R39,"")&IF((BP39-ROUNDDOWN(BP39,-1))=S39,T39,""),"")))) | BL39: =IF(BP39="","",IF(BP39>59,"",IF(BP39>=50,"fifty "&IF((BP39-ROUNDDOWN(BP39,-1))=1,D39,"")&IF((BP39-ROUNDDOWN(BP39,-1))=2,F39,"")&IF((BP39-ROUNDDOWN(BP39,-1))=G39,H39,"")&IF((BP39-ROUNDDOWN(BP39,-1))=I39,J39,"")&IF((BP39-ROUNDDOWN(BP39,-1))=K39,L39,"")&IF((BP39-ROUNDDOWN(BP39,-1))=M39,N39,"")&IF((BP39-ROUNDDOWN(BP39,-1))=O39,P39,"")&IF((BP39-ROUNDDOWN(BP39,-1))=Q39,R39,"")&IF((BP39-ROUNDDOWN(BP39,-1))=S39,T39,""),IF(BP39>=40,"forty "&IF((BP39-ROUNDDOWN(BP39,-1))=1,D39,"")&IF((BP39-ROUNDDOWN(BP39,-1))=2,F39,"")&IF((BP39-ROUNDDOWN(BP39,-1))=G39,H39,"")&IF((BP39-ROUNDDOWN(BP39,-1))=I39,J39,"")&IF((BP39-ROUNDDOWN(BP39,-1))=K39,L39,"")&IF((BP39-ROUNDDOWN(BP39,-1))=M39,N39,"")&IF((BP39-ROUNDDOWN(BP39,-1))=O39,P39,"")&IF((BP39-ROUNDDOWN(BP39,-1))=Q39,R39,"")&IF((BP39-ROUNDDOWN(BP39,-1))=S39,T39,""),"")))) | BM39: =IF(BP39="","",IF(BP39>39,"",IF(BP39>=30,"thirty "&IF((BP39-ROUNDDOWN(BP39,-1))=1,D39,"")&IF((BP39-ROUNDDOWN(BP39,-1))=2,F39,"")&IF((BP39-ROUNDDOWN(BP39,-1))=G39,H39,"")&IF((BP39-ROUNDDOWN(BP39,-1))=I39,J39,"")&IF((BP39-ROUNDDOWN(BP39,-1))=K39,L39,"")&IF((BP39-ROUNDDOWN(BP39,-1))=M39,N39,"")&IF((BP39-ROUNDDOWN(BP39,-1))=O39,P39,"")&IF((BP39-ROUNDDOWN(BP39,-1))=Q39,R39,"")&IF((BP39-ROUNDDOWN(BP39,-1))=S39,T39,""),IF(BP39>=20,"twenty "&IF((BP39-ROUNDDOWN(BP39,-1))=1,D39,"")&IF((BP39-ROUNDDOWN(BP39,-1))=2,F39,"")&IF((BP39-ROUNDDOWN(BP39,-1))=G39,H39,"")&IF((BP39-ROUNDDOWN(BP39,-1))=I39,J39,"")&IF((BP39-ROUNDDOWN(BP39,-1))=K39,L39,"")&IF((BP39-ROUNDDOWN(BP39,-1))=M39,N39,"")&IF((BP39-ROUNDDOWN(BP39,-1))=O39,P39,"")&IF((BP39-ROUNDDOWN(BP39,-1))=Q39,R39,"")&IF((BP39-ROUNDDOWN(BP39,-1))=S39,T39,""),"")))) -> twenty three | BN39: =IF(BP39="","",IF(BP39=C39,D39,"")&IF(BP39=E39,F39,"")&IF(BP39=G39,H39,"")&IF(BP39=I39,J39,"")&IF(BP39=K39,L39,"")&IF(BP39=M39,N39,"")&IF(BP39=O39,P39,"")&IF(BP39=Q39,R39,"")&IF(BP39=S39,T39,"")&IF(BP39=U39,V39,"")&IF(BP39=W39,X39,"")&IF(BP39=Y39,Z39,"")&IF(BP39=AA39,AB39,"")&IF(BP39=AC39,AD39,"")&IF(BP39=AE39,AF39,"")&IF(BP39=AG39,AH39,"")&IF(BP39=AI39,AJ39,"")&IF(BP39=AK39,AL39,"")&IF(BP39=AM39,AN39,"")) | BP39: =IF(A39>=1000,ROUNDDOWN((A39-ROUNDDOWN(A39,-5))/1000,0),"") -> 23 | BQ39: =IF(BJ39="","",BJ39)&IF(BK39="","",BK39)&IF(BL39="","",BL39)&IF(BM39="","",BM39)&IF(BN39="","",BN39) -> twenty three | BR39: HUNDRED | BS39: =IF(BY39="","",IF(BY39>=90,"ninety "&IF((BY39-ROUNDDOWN(BY39,-1))=1,D39,"")&IF((BY39-ROUNDDOWN(BY39,-1))=2,F39,"")&IF((BY39-ROUNDDOWN(BY39,-1))=G39,H39,"")&IF((BY39-ROUNDDOWN(BY39,-1))=I39,J39,"")&IF((BY39-ROUNDDOWN(BY39,-1))=K39,L39,"")&IF((BY39-ROUNDDOWN(BY39,-1))=M39,N39,"")&IF((BY39-ROUNDDOWN(BY39,-1))=O39,P39,"")&IF((BY39-ROUNDDOWN(BY39,-1))=Q39,R39,"")&IF((BY39-ROUNDDOWN(BY39,-1))=S39,T39,""),IF(BY39>=80,"eighty "&IF((BY39-ROUNDDOWN(BY39,-1))=1,D39,"")&IF((BY39-ROUNDDOWN(BY39,-1))=2,F39,"")&IF((BY39-ROUNDDOWN(BY39,-1))=G39,H39,"")&IF((BY39-ROUNDDOWN(BY39,-1))=I39,J39,"")&IF((BY39-ROUNDDOWN(BY39,-1))=K39,L39,"")&IF((BY39-ROUNDDOWN(BY39,-1))=M39,N39,"")&IF((BY39-ROUNDDOWN(BY39,-1))=O39,P39,"")&IF((BY39-ROUNDDOWN(BY39,-1))=Q39,R39,"")&IF((BY39-ROUNDDOWN(BY39,-1))=S39,T39,""),""))) | BT39: =IF(BY39="","",IF(BY39>79,"",IF(BY39>=70,"seventy "&IF((BY39-ROUNDDOWN(BY39,-1))=1,D39,"")&IF((BY39-ROUNDDOWN(BY39,-1))=2,F39,"")&IF((BY39-ROUNDDOWN(BY39,-1))=G39,H39,"")&IF((BY39-ROUNDDOWN(BY39,-1))=I39,J39,"")&IF((BY39-ROUNDDOWN(BY39,-1))=K39,L39,"")&IF((BY39-ROUNDDOWN(BY39,-1))=M39,N39,"")&IF((BY39-ROUNDDOWN(BY39,-1))=O39,P39,"")&IF((BY39-ROUNDDOWN(BY39,-1))=Q39,R39,"")&IF((BY39-ROUNDDOWN(BY39,-1))=S39,T39,""),IF(BY39>=60,"sixty "&IF((BY39-ROUNDDOWN(BY39,-1))=1,D39,"")&IF((BY39-ROUNDDOWN(BY39,-1))=2,F39,"")&IF((BY39-ROUNDDOWN(BY39,-1))=G39,H39,"")&IF((BY39-ROUNDDOWN(BY39,-1))=I39,J39,"")&IF((BY39-ROUNDDOWN(BY39,-1))=K39,L39,"")&IF((BY39-ROUNDDOWN(BY39,-1))=M39,N39,"")&IF((BY39-ROUNDDOWN(BY39,-1))=O39,P39,"")&IF((BY39-ROUNDDOWN(BY39,-1))=Q39,R39,"")&IF((BY39-ROUNDDOWN(BY39,-1))=S39,T39,""),"")))) | BU39: =IF(BY39="","",IF(BY39>59,"",IF(BY39>=50,"fifty "&IF((BY39-ROUNDDOWN(BY39,-1))=1,D39,"")&IF((BY39-ROUNDDOWN(BY39,-1))=2,F39,"")&IF((BY39-ROUNDDOWN(BY39,-1))=G39,H39,"")&IF((BY39-ROUNDDOWN(BY39,-1))=I39,J39,"")&IF((BY39-ROUNDDOWN(BY39,-1))=K39,L39,"")&IF((BY39-ROUNDDOWN(BY39,-1))=M39,N39,"")&IF((BY39-ROUNDDOWN(BY39,-1))=O39,P39,"")&IF((BY39-ROUNDDOWN(BY39,-1))=Q39,R39,"")&IF((BY39-ROUNDDOWN(BY39,-1))=S39,T39,""),IF(BY39>=40,"forty "&IF((BY39-ROUNDDOWN(BY39,-1))=1,D39,"")&IF((BY39-ROUNDDOWN(BY39,-1))=2,F39,"")&IF((BY39-ROUNDDOWN(BY39,-1))=G39,H39,"")&IF((BY39-ROUNDDOWN(BY39,-1))=I39,J39,"")&IF((BY39-ROUNDDOWN(BY39,-1))=K39,L39,"")&IF((BY39-ROUNDDOWN(BY39,-1))=M39,N39,"")&IF((BY39-ROUNDDOWN(BY39,-1))=O39,P39,"")&IF((BY39-ROUNDDOWN(BY39,-1))=Q39,R39,"")&IF((BY39-ROUNDDOWN(BY39,-1))=S39,T39,""),"")))) | BV39: =IF(BY39="","",IF(BY39>39,"",IF(BY39>=30,"thirty "&IF((BY39-ROUNDDOWN(BY39,-1))=1,D39,"")&IF((BY39-ROUNDDOWN(BY39,-1))=2,F39,"")&IF((BY39-ROUNDDOWN(BY39,-1))=G39,H39,"")&IF((BY39-ROUNDDOWN(BY39,-1))=I39,J39,"")&IF((BY39-ROUNDDOWN(BY39,-1))=K39,L39,"")&IF((BY39-ROUNDDOWN(BY39,-1))=M39,N39,"")&IF((BY39-ROUNDDOWN(BY39,-1))=O39,P39,"")&IF((BY39-ROUNDDOWN(BY39,-1))=Q39,R39,"")&IF((BY39-ROUNDDOWN(BY39,-1))=S39,T39,""),IF(BY39>=20,"twenty "&IF((BY39-ROUNDDOWN(BY39,-1))=1,D39,"")&IF((BY39-ROUNDDOWN(BY39,-1))=2,F39,"")&IF((BY39-ROUNDDOWN(BY39,-1))=G39,H39,"")&IF((BY39-ROUNDDOWN(BY39,-1))=I39,J39,"")&IF((BY39-ROUNDDOWN(BY39,-1))=K39,L39,"")&IF((BY39-ROUNDDOWN(BY39,-1))=M39,N39,"")&IF((BY39-ROUNDDOWN(BY39,-1))=O39,P39,"")&IF((BY39-ROUNDDOWN(BY39,-1))=Q39,R39,"")&IF((BY39-ROUNDDOWN(BY39,-1))=S39,T39,""),"")))) | BW39: =IF(BY39="","",IF(BY39=C39,D39,"")&IF(BY39=E39,F39,"")&IF(BY39=G39,H39,"")&IF(BY39=I39,J39,"")&IF(BY39=K39,L39,"")&IF(BY39=M39,N39,"")&IF(BY39=O39,P39,"")&IF(BY39=Q39,R39,"")&IF(BY39=S39,T39,"")&IF(BY39=U39,V39,"")&IF(BY39=W39,X39,"")&IF(BY39=Y39,Z39,"")&IF(BY39=AA39,AB39,"")&IF(BY39=AC39,AD39,"")&IF(BY39=AE39,AF39,"")&IF(BY39=AG39,AH39,"")&IF(BY39=AI39,AJ39,"")&IF(BY39=AK39,AL39,"")&IF(BY39=AM39,AN39,"")) -> five | BY39: =IF(A39>=100,ROUNDDOWN((A39-ROUNDDOWN(A39,-3))/100,0),"") -> 5 | BZ39: =IF(BS39="","",BS39)&IF(BT39="","",BT39)&IF(BU39="","",BU39)&IF(BV39="","",BV39)&IF(BW39="","",BW39) -> five | CA39: TENS | CB39: =IF(CH39="","",IF(CH39>=90,"ninety "&IF((CH39-ROUNDDOWN(CH39,-1))=1,D39,"")&IF((CH39-ROUNDDOWN(CH39,-1))=2,F39,"")&IF((CH39-ROUNDDOWN(CH39,-1))=G39,H39,"")&IF((CH39-ROUNDDOWN(CH39,-1))=I39,J39,"")&IF((CH39-ROUNDDOWN(CH39,-1))=K39,L39,"")&IF((CH39-ROUNDDOWN(CH39,-1))=M39,N39,"")&IF((CH39-ROUNDDOWN(CH39,-1))=O39,P39,"")&IF((CH39-ROUNDDOWN(CH39,-1))=Q39,R39,"")&IF((CH39-ROUNDDOWN(CH39,-1))=S39,T39,""),IF(CH39>=80,"eighty "&IF((CH39-ROUNDDOWN(CH39,-1))=1,D39,"")&IF((CH39-ROUNDDOWN(CH39,-1))=2,F39,"")&IF((CH39-ROUNDDOWN(CH39,-1))=G39,H39,"")&IF((CH39-ROUNDDOWN(CH39,-1))=I39,J39,"")&IF((CH39-ROUNDDOWN(CH39,-1))=K39,L39,"")&IF((CH39-ROUNDDOWN(CH39,-1))=M39,N39,"")&IF((CH39-ROUNDDOWN(CH39,-1))=O39,P39,"")&IF((CH39-ROUNDDOWN(CH39,-1))=Q39,R39,"")&IF((CH39-ROUNDDOWN(CH39,-1))=S39,T39,""),""))) | CC39: =IF(CH39="","",IF(CH39>79,"",IF(CH39>=70,"seventy "&IF((CH39-ROUNDDOWN(CH39,-1))=1,D39,"")&IF((CH39-ROUNDDOWN(CH39,-1))=2,F39,"")&IF((CH39-ROUNDDOWN(CH39,-1))=G39,H39,"")&IF((CH39-ROUNDDOWN(CH39,-1))=I39,J39,"")&IF((CH39-ROUNDDOWN(CH39,-1))=K39,L39,"")&IF((CH39-ROUNDDOWN(CH39,-1))=M39,N39,"")&IF((CH39-ROUNDDOWN(CH39,-1))=O39,P39,"")&IF((CH39-ROUNDDOWN(CH39,-1))=Q39,R39,"")&IF((CH39-ROUNDDOWN(CH39,-1))=S39,T39,""),IF(CH39>=60,"sixty "&IF((CH39-ROUNDDOWN(CH39,-1))=1,D39,"")&IF((CH39-ROUNDDOWN(CH39,-1))=2,F39,"")&IF((CH39-ROUNDDOWN(CH39,-1))=G39,H39,"")&IF((CH39-ROUNDDOWN(CH39,-1))=I39,J39,"")&IF((CH39-ROUNDDOWN(CH39,-1))=K39,L39,"")&IF((CH39-ROUNDDOWN(CH39,-1))=M39,N39,"")&IF((CH39-ROUNDDOWN(CH39,-1))=O39,P39,"")&IF((CH39-ROUNDDOWN(CH39,-1))=Q39,R39,"")&IF((CH39-ROUNDDOWN(CH39,-1))=S39,T39,""),"")))) | CD39: =IF(CH39="","",IF(CH39>59,"",IF(CH39>=50,"fifty "&IF((CH39-ROUNDDOWN(CH39,-1))=1,D39,"")&IF((CH39-ROUNDDOWN(CH39,-1))=2,F39,"")&IF((CH39-ROUNDDOWN(CH39,-1))=G39,H39,"")&IF((CH39-ROUNDDOWN(CH39,-1))=I39,J39,"")&IF((CH39-ROUNDDOWN(CH39,-1))=K39,L39,"")&IF((CH39-ROUNDDOWN(CH39,-1))=M39,N39,"")&IF((CH39-ROUNDDOWN(CH39,-1))=O39,P39,"")&IF((CH39-ROUNDDOWN(CH39,-1))=Q39,R39,"")&IF((CH39-ROUNDDOWN(CH39,-1))=S39,T39,""),IF(CH39>=40,"forty "&IF((CH39-ROUNDDOWN(CH39,-1))=1,D39,"")&IF((CH39-ROUNDDOWN(CH39,-1))=2,F39,"")&IF((CH39-ROUNDDOWN(CH39,-1))=G39,H39,"")&IF((CH39-ROUNDDOWN(CH39,-1))=I39,J39,"")&IF((CH39-ROUNDDOWN(CH39,-1))=K39,L39,"")&IF((CH39-ROUNDDOWN(CH39,-1))=M39,N39,"")&IF((CH39-ROUNDDOWN(CH39,-1))=O39,P39,"")&IF((CH39-ROUNDDOWN(CH39,-1))=Q39,R39,"")&IF((CH39-ROUNDDOWN(CH39,-1))=S39,T39,""),"")))) | CE39: =IF(CH39="","",IF(CH39>39,"",IF(CH39>=30,"thirty "&IF((CH39-ROUNDDOWN(CH39,-1))=1,D39,"")&IF((CH39-ROUNDDOWN(CH39,-1))=2,F39,"")&IF((CH39-ROUNDDOWN(CH39,-1))=G39,H39,"")&IF((CH39-ROUNDDOWN(CH39,-1))=I39,J39,"")&IF((CH39-ROUNDDOWN(CH39,-1))=K39,L39,"")&IF((CH39-ROUNDDOWN(CH39,-1))=M39,N39,"")&IF((CH39-ROUNDDOWN(CH39,-1))=O39,P39,"")&IF((CH39-ROUNDDOWN(CH39,-1))=Q39,R39,"")&IF((CH39-ROUNDDOWN(CH39,-1))=S39,T39,""),IF(CH39>=20,"twenty "&IF((CH39-ROUNDDOWN(CH39,-1))=1,D39,"")&IF((CH39-ROUNDDOWN(CH39,-1))=2,F39,"")&IF((CH39-ROUNDDOWN(CH39,-1))=G39,H39,"")&IF((CH39-ROUNDDOWN(CH39,-1))=I39,J39,"")&IF((CH39-ROUNDDOWN(CH39,-1))=K39,L39,"")&IF((CH39-ROUNDDOWN(CH39,-1))=M39,N39,"")&IF((CH39-ROUNDDOWN(CH39,-1))=O39,P39,"")&IF((CH39-ROUNDDOWN(CH39,-1))=Q39,R39,"")&IF((CH39-ROUNDDOWN(CH39,-1))=S39,T39,""),"")))) | CF39: =IF(CH39="","",IF(CH39=C39,D39,"")&IF(CH39=E39,F39,"")&IF(CH39=G39,H39,"")&IF(CH39=I39,J39,"")&IF(CH39=K39,L39,"")&IF(CH39=M39,N39,"")&IF(CH39=O39,P39,"")&IF(CH39=Q39,R39,"")&IF(CH39=S39,T39,"")&IF(CH39=U39,V39,"")&IF(CH39=W39,X39,"")&IF(CH39=Y39,Z39,"")&IF(CH39=AA39,AB39,"")&IF(CH39=AC39,AD39,"")&IF(CH39=AE39,AF39,"")&IF(CH39=AG39,AH39,"")&IF(CH39=AI39,AJ39,"")&IF(CH39=AK39,AL39,"")&IF(CH39=AM39,AN39,"")) | CH39: =IF(A39>=1,ROUNDDOWN(A39-ROUNDDOWN(A39,-2),0),"") -> 0 | CI39: =IF(CB39="","",CB39)&IF(CC39="","",CC39)&IF(CD39="","",CD39)&IF(CE39="","",CE39)&IF(CF39="","",CF39) | CJ39: PAISE | CK39: =IF(CQ39="","",IF(CQ39>=90,"ninety "&IF((CQ39-ROUNDDOWN(CQ39,-1))=1,D39,"")&IF((CQ39-ROUNDDOWN(CQ39,-1))=2,F39,"")&IF((CQ39-ROUNDDOWN(CQ39,-1))=G39,H39,"")&IF((CQ39-ROUNDDOWN(CQ39,-1))=I39,J39,"")&IF((CQ39-ROUNDDOWN(CQ39,-1))=K39,L39,"")&IF((CQ39-ROUNDDOWN(CQ39,-1))=M39,N39,"")&IF((CQ39-ROUNDDOWN(CQ39,-1))=O39,P39,"")&IF((CQ39-ROUNDDOWN(CQ39,-1))=Q39,R39,"")&IF((CQ39-ROUNDDOWN(CQ39,-1))=S39,T39,""),IF(CQ39>=80,"eighty "&IF((CQ39-ROUNDDOWN(CQ39,-1))=1,D39,"")&IF((CQ39-ROUNDDOWN(CQ39,-1))=2,F39,"")&IF((CQ39-ROUNDDOWN(CQ39,-1))=G39,H39,"")&IF((CQ39-ROUNDDOWN(CQ39,-1))=I39,J39,"")&IF((CQ39-ROUNDDOWN(CQ39,-1))=K39,L39,"")&IF((CQ39-ROUNDDOWN(CQ39,-1))=M39,N39,"")&IF((CQ39-ROUNDDOWN(CQ39,-1))=O39,P39,"")&IF((CQ39-ROUNDDOWN(CQ39,-1))=Q39,R39,"")&IF((CQ39-ROUNDDOWN(CQ39,-1))=S39,T39,""),""))) | CL39: =IF(CQ39="","",IF(CQ39>79,"",IF(CQ39>=70,"seventy "&IF((CQ39-ROUNDDOWN(CQ39,-1))=1,D39,"")&IF((CQ39-ROUNDDOWN(CQ39,-1))=2,F39,"")&IF((CQ39-ROUNDDOWN(CQ39,-1))=G39,H39,"")&IF((CQ39-ROUNDDOWN(CQ39,-1))=I39,J39,"")&IF((CQ39-ROUNDDOWN(CQ39,-1))=K39,L39,"")&IF((CQ39-ROUNDDOWN(CQ39,-1))=M39,N39,"")&IF((CQ39-ROUNDDOWN(CQ39,-1))=O39,P39,"")&IF((CQ39-ROUNDDOWN(CQ39,-1))=Q39,R39,"")&IF((CQ39-ROUNDDOWN(CQ39,-1))=S39,T39,""),IF(CQ39>=60,"sixty "&IF((CQ39-ROUNDDOWN(CQ39,-1))=1,D39,"")&IF((CQ39-ROUNDDOWN(CQ39,-1))=2,F39,"")&IF((CQ39-ROUNDDOWN(CQ39,-1))=G39,H39,"")&IF((CQ39-ROUNDDOWN(CQ39,-1))=I39,J39,"")&IF((CQ39-ROUNDDOWN(CQ39,-1))=K39,L39,"")&IF((CQ39-ROUNDDOWN(CQ39,-1))=M39,N39,"")&IF((CQ39-ROUNDDOWN(CQ39,-1))=O39,P39,"")&IF((CQ39-ROUNDDOWN(CQ39,-1))=Q39,R39,"")&IF((CQ39-ROUNDDOWN(CQ39,-1))=S39,T39,""),"")))) | CM39: =IF(CQ39="","",IF(CQ39>59,"",IF(CQ39>=50,"fifty "&IF((CQ39-ROUNDDOWN(CQ39,-1))=1,D39,"")&IF((CQ39-ROUNDDOWN(CQ39,-1))=2,F39,"")&IF((CQ39-ROUNDDOWN(CQ39,-1))=G39,H39,"")&IF((CQ39-ROUNDDOWN(CQ39,-1))=I39,J39,"")&IF((CQ39-ROUNDDOWN(CQ39,-1))=K39,L39,"")&IF((CQ39-ROUNDDOWN(CQ39,-1))=M39,N39,"")&IF((CQ39-ROUNDDOWN(CQ39,-1))=O39,P39,"")&IF((CQ39-ROUNDDOWN(CQ39,-1))=Q39,R39,"")&IF((CQ39-ROUNDDOWN(CQ39,-1))=S39,T39,""),IF(CQ39>=40,"forty "&IF((CQ39-ROUNDDOWN(CQ39,-1))=1,D39,"")&IF((CQ39-ROUNDDOWN(CQ39,-1))=2,F39,"")&IF((CQ39-ROUNDDOWN(CQ39,-1))=G39,H39,"")&IF((CQ39-ROUNDDOWN(CQ39,-1))=I39,J39,"")&IF((CQ39-ROUNDDOWN(CQ39,-1))=K39,L39,"")&IF((CQ39-ROUNDDOWN(CQ39,-1))=M39,N39,"")&IF((CQ39-ROUNDDOWN(CQ39,-1))=O39,P39,"")&IF((CQ39-ROUNDDOWN(CQ39,-1))=Q39,R39,"")&IF((CQ39-ROUNDDOWN(CQ39,-1))=S39,T39,""),"")))) | CN39: =IF(CQ39="","",IF(CQ39>39,"",IF(CQ39>=30,"thirty "&IF((CQ39-ROUNDDOWN(CQ39,-1))=1,D39,"")&IF((CQ39-ROUNDDOWN(CQ39,-1))=2,F39,"")&IF((CQ39-ROUNDDOWN(CQ39,-1))=G39,H39,"")&IF((CQ39-ROUNDDOWN(CQ39,-1))=I39,J39,"")&IF((CQ39-ROUNDDOWN(CQ39,-1))=K39,L39,"")&IF((CQ39-ROUNDDOWN(CQ39,-1))=M39,N39,"")&IF((CQ39-ROUNDDOWN(CQ39,-1))=O39,P39,"")&IF((CQ39-ROUNDDOWN(CQ39,-1))=Q39,R39,"")&IF((CQ39-ROUNDDOWN(CQ39,-1))=S39,T39,""),IF(CQ39>=20,"twenty "&IF((CQ39-ROUNDDOWN(CQ39,-1))=1,D39,"")&IF((CQ39-ROUNDDOWN(CQ39,-1))=2,F39,"")&IF((CQ39-ROUNDDOWN(CQ39,-1))=G39,H39,"")&IF((CQ39-ROUNDDOWN(CQ39,-1))=I39,J39,"")&IF((CQ39-ROUNDDOWN(CQ39,-1))=K39,L39,"")&IF((CQ39-ROUNDDOWN(CQ39,-1))=M39,N39,"")&IF((CQ39-ROUNDDOWN(CQ39,-1))=O39,P39,"")&IF((CQ39-ROUNDDOWN(CQ39,-1))=Q39,R39,"")&IF((CQ39-ROUNDDOWN(CQ39,-1))=S39,T39,""),"")))) | CO39: =IF(CQ39="","",IF(CQ39=C39,D39,"")&IF(CQ39=E39,F39,"")&IF(CQ39=G39,H39,"")&IF(CQ39=I39,J39,"")&IF(CQ39=K39,L39,"")&IF(CQ39=M39,N39,"")&IF(CQ39=O39,P39,"")&IF(CQ39=Q39,R39,"")&IF(CQ39=S39,T39,"")&IF(CQ39=U39,V39,"")&IF(CQ39=W39,X39,"")&IF(CQ39=Y39,Z39,"")&IF(CQ39=AA39,AB39,"")&IF(CQ39=AC39,AD39,"")&IF(CQ39=AE39,AF39,"")&IF(CQ39=AG39,AH39,"")&IF(CQ39=AI39,AJ39,"")&IF(CQ39=AK39,AL39,"")&IF(CQ39=AM39,AN39,"")) | CQ39: =IF((A39-ROUNDDOWN(A39,0))>0,ROUND((A39-ROUNDDOWN(A39,0))*100,0),"") | CR39: =IF(CK39="","",CK39)&IF(CL39="","",CL39)&IF(CM39="","",CM39)&IF(CN39="","",CN39)&IF(CO39="","",CO39) | CS39: <= IN WORDS | CU39: =IF(A39="","","(Rupees "&IF(AY39="","",AY39&" crore ")&IF(BH39="","",BH39&" lakh ")&IF(BQ39="","",BQ39&" thousand ")&IF(BZ39="","",BZ39&" hundred ")&IF(CI39="","",CI39)&IF(CR39="",""," and paise "&CR39)&") only.") -> (Rupees forty eight lakh twenty three thousand five hundred ) only.

Sheet Rennovation Measurement
A1: Name of Work :- Repairing and Renovation of Circuit House at Bokakhat Co District under Golaghat District
A2: (Rates are quoted from DSR (civil) of 2021)
A3: DETAIL ESTIMATE
A4: SL. No. | B4: CODE NO | C4: PARTICULARS | K4: QTY | L4: Unit | M4: RATE | N4: AMOUNT
A6: 1 | B6: 15.7 | C6: Demolishing brick work manually/ by mechanical means including stacking of serviceable material and disposal of unserviceable material within 50 metres lead as per direction of Engineer-in-charge.15.7.4 in cement mortar
C7: In cement mortar | D7: 1 | E7: x | F7: 10.45 | G7: x | H7: 0.12 | I7: x | J7: 0.78 | K7: =D7*F7*H7*J7 -> 0.98 | L7: Cum
C8: In cement mortar | D8: 1 | E8: x | F8: 2.3 | G8: x | H8: 0.12 | I8: x | J8: 2.1 | K8: =D8*F8*H8*J8 -> 0.58 | L8: Cum
C9: Total | K9: =ROUND(SUM(K7:K8), 2) -> 1.56 | L9: Cum | M9: 1698.45 | N9: =ROUND(K9*M9, 2) -> 2649.58
A10: 2 | B10: 15.23.1 | C10: Dismantling tile work in floors and roofs laid in cement mortar including stacking material within 50 metres lead. 15.23.1 For thickness of tiles 10 mm to 25 mm
C11: Ground floor.Toilet | D11: 3 | E11: x | F11: 3.15 | I11: x | J11: 1.45 | K11: =D11*F11*J11 -> 13.7 | L11: Sqm
C12: Ground floor.Toilet | D12: 1 | E12: x | F12: 2.05 | I12: x | J12: 1.45 | K12: =D12*F12*J12 -> 2.97 | L12: Sqm
C13: Ground floor.Toilet | D13: 3 | E13: x | F13: 9.2 | I13: x | J13: 1.5 | K13: =D13*F13*J13 -> 41.4 | L13: Sqm
C14: Ground floor.Toilet | D14: 1 | E14: x | F14: 7 | I14: x | J14: 2.1 | K14: =D14*F14*J14 -> 14.7 | L14: Sqm
C15: First floor.Toilet | D15: 4 | E15: x | F15: 3.8 | I15: x | J15: 1.8 | K15: =D15*F15*J15 -> 27.36 | L15: Sqm
C16: First floor.Toilet | D16: 4 | E16: x | F16: 11.2 | I16: x | J16: 2.1 | K16: =D16*F16*J16 -> 94.08 | L16: Sqm
C17: A-Type Cottage Room 1 | D17: 1 | E17: x | F17: 5 | I17: x | J17: 7.5 | K17: =D17*F17*J17 -> 37.5 | L17: Sqm
C18: A-Type Cottage Room 2 | D18: 1 | E18: x | F18: 2.2 | I18: x | J18: 2.5 | K18: =D18*F18*J18 -> 5.5 | L18: Sqm
C19: Total | K19: =ROUND(SUM(K11:K18), 2) -> 237.21 | L19: Sqm | M19: 60.5 | N19: =ROUND(K19*M19, 2) -> 14351.21
A20: 3 | B20: 15.28 | C20: Dismantling roofing including ridges, hips, valleys and gutters etc., and stacking the material within 50 metres lead of: 15.28.1G.S. Sheet
C21: G.S. Sheet | D21: 2 | E21: x | F21: 2.1 | I21: x | J21: 0.85 | K21: =D21*F21*J21 -> 3.57 | L21: Sqm
C22: Total | K22: =ROUND(SUM(K21:K21), 2) -> 3.57 | L22: Sqm | M22: 136 | N22: =ROUND(K22*M22, 2) -> 485.52
A23: 4 | B23: 2.25 | C23: Filling available excavated earth (excluding rock) in trenches, plinth, sides of foundations etc. in layers not exceeding 20cm in depth, consolidating each deposited layer by ramming and watering, lead up to 50 m and lift upto 1.5 m.
C24: Plinth & trenches | D24: 1 | E24: x | F24: 7.7 | G24: x | H24: 2.6 | I24: x | J24: 0.65 | K24: =D24*F24*H24*J24 -> 13.01 | L24: Cum
C25: Total | K25: =ROUND(SUM(K24:K24), 2) -> 13.01 | L25: Cum | M25: 253.95 | N25: =ROUND(K25*M25, 2) -> 3303.89
A26: 5 | B26: 11.2 | C26: Dry brick on edge flooring in required pattern with bricks of class designation 7.5 on a bed of 12 mm mud mortar, including filling joints with Jamuna sand, with common burnt clay non modular bricks.
C27: Flooring area | D27: 1 | E27: x | F27: 6 | I27: x | J27: 1.65 | K27: =D27*F27*J27 -> 9.9 | L27: Sqm
C28: Total | K28: =ROUND(SUM(K27:K27), 2) -> 9.9 | L28: Sqm | M28: 733.3 | N28: =ROUND(K28*M28, 2) -> 7259.67
A29: 6 | B29: 11.5 | C29: 62 mm thick cement concrete flooring with concrete hardener topping, under layer 50 mm thick cement concrete 1:2:4 (1 cement : 2 coarse sand : 4 graded stone aggregate 20mm nominal size) and top layer 12mm thick cement hardener consisting of mix 1:2 (1 cement hardener mix : 2 graded stone aggregate, 6mm nominal size) by volume, hardening compound mixed @ 2 litre per 50 kg of cement or as per manufacture’s specifications. This includes cost of cement slurry, but excluding the cost of nosing of steps etc. complete.
C30: Flooring area | D30: 1 | E30: x | F30: 6 | I30: x | J30: 1.65 | K30: =D30*F30*J30 -> 9.9 | L30: Sqm
C31: Total | K31: =ROUND(SUM(K30:K30), 2) -> 9.9 | L31: Sqm | M31: 928.65 | N31: =ROUND(K31*M31, 2) -> 9193.64
A32: 7 | B32: 11.41 | C32: Providing and laying vitrified floor tiles in different sizes (thickness to be specified by the manufacturer) with water absorption less than 0.08% and conforming to IS: 15622, of approved make, in all colours and shades, laid on 20mm thick cement mortar 1:4 (1 cement : 4 coarse sand), jointing with grey cement slurry @ 3.3 kg/ sqm including grouting the joints with white cement and matching pigments etc., complete. 11.41.2 Size of Tile 600x600 mm.
C33: Existing Kitchen | D33: 1 | E33: x | F33: 6 | I33: x | J33: 3.55 | K33: =D33*F33*J33 -> 21.3 | L33: Sqm
C34: Chawkidar room | D34: 1 | E34: x | F34: 2.95 | I34: x | J34: 3.6 | K34: =D34*F34*J34 -> 10.62 | L34: Sqm
C35: Verandah | D35: 1 | E35: x | F35: 4.25 | I35: x | J35: 7.5 | K35: =D35*F35*J35 -> 31.88 | L35: Sqm
C36: Ground floor toilet | D36: 3 | E36: x | F36: 3.15 | I36: x | J36: 1.45 | K36: =D36*F36*J36 -> 13.7 | L36: Sqm
C37: Ground floor toilet | D37: 1 | E37: x | F37: 2.05 | I37: x | J37: 1.45 | K37: =D37*F37*J37 -> 2.97 | L37: Sqm
C38: First floor toilet | D38: 4 | E38: x | F38: 3.8 | I38: x | J38: 1.8 | K38: =D38*F38*J38 -> 27.36 | L38: Sqm
C39: Dormitory | D39: 1 | E39: x | F39: 9.15 | I39: x | J39: 6 | K39: =D39*F39*J39 -> 54.9 | L39: Sqm
C40: Dormitory portion | D40: 1 | E40: x | F40: 6.4 | I40: x | J40: 3.5 | K40: =D40*F40*J40 -> 22.4 | L40: Sqm
C41: Dormitory portion | D41: 1 | E41: x | F41: 6.4 | I41: x | J41: 1.85 | K41: =D41*F41*J41 -> 11.84 | L41: Sqm
...

Sheet Rennovation BOQ
A1: ='AType Cottage'!A1 -> Name of Work :- Repairing and Renovation of Circuit House at Bokakhat Co District under Golaghat District
A2: ITEM NO. | B2: Sl No | C2: DESCRIPTION OF ITEM | J2: Qty | K2: UNIT | L2: RATE Rs | M2: AMOUNT
A3: 1 | B3: 15.7 | C3: Demolishing brick work manually/ by mechanical means including stacking of serviceable material and disposal of unserviceable material within 50 metres lead as per direction of Engineer-in-charge.15.7.4 in cement mortar | J3: ='Rennovation Measurement'!K9 -> 1.56 | K3: Cum | L3: 1698.45 | M3: =ROUND(J3*L3,0) -> 2650 | P3: =+J3*L3 -> 2649.58
A4: 2 | B4: 15.23.1 | C4: Dismantling tile work in floors and roofs laid in cement mortar including stacking material within 50 metres lead. 15.23.1 For thickness of tiles 10 mm to 25 mm | J4: ='Rennovation Measurement'!K19 -> 237.21 | K4: Sqm | L4: 60.5 | M4: =ROUND(J4*L4,0) -> 14351 | O4: =5.95+3.1 -> 9.05
A5: 3 | B5: 15.28 | C5: Dismantling roofing including ridges, hips, valleys and gutters etc., and stacking the material within 50 metres lead of: 15.28.1G.S. Sheet | J5: ='Rennovation Measurement'!K22 -> 3.57 | K5: Sqm | L5: 136 | M5: =ROUND(J5*L5,0) -> 486
A6: 4 | B6: 2.25 | C6: Filling available excavated earth (excluding rock) in trenches, plinth, sides of foundations etc. in layers not exceeding 20cm in depth, consolidating each deposited layer by ramming and watering, lead up to 50 m and lift upto 1.5 m. | J6: ='Rennovation Measurement'!K25 -> 13.01 | K6: Cum | L6: 253.95 | M6: =ROUND(J6*L6,0) -> 3304
A7: 5 | B7: 11.2 | C7: Dry brick on edge flooring in required pattern with bricks of class designation 7.5 on a bed of 12 mm mud mortar, including filling joints with Jamuna sand, with common burnt clay non modular bricks. | J7: ='Rennovation Measurement'!K28 -> 9.9 | K7: Sqm | L7: 733.3 | M7: =ROUND(J7*L7,0) -> 7260
A8: 6 | B8: 11.5 | C8: 62 mm thick cement concrete flooring with concrete hardener topping, under layer 50 mm thick cement concrete 1:2:4 (1 cement : 2 coarse sand : 4 graded stone aggregate 20mm nominal size) and top layer 12mm thick cement hardener consisting of mix 1:2 (1 cement hardener mix : 2 graded stone aggregate, 6mm nominal size) by volume, hardening compound mixed @ 2 litre per 50 kg of cement or as per manufacture’s specifications. This includes cost of cement slurry, but excluding the cost of nosing of steps etc. complete. | J8: ='Rennovation Measurement'!K31 -> 9.9 | K8: Sqm | L8: 928.65 | M8: =ROUND(J8*L8,0) -> 9194
A9: 7 | B9: 11.41 | C9: Providing and laying vitrified floor tiles in different sizes (thickness to be specified by the manufacturer) with water absorption less than 0.08% and conforming to IS: 15622, of approved make, in all colours and shades, laid on 20mm thick cement mortar 1:4 (1 cement : 4 coarse sand), jointing with grey cement slurry @ 3.3 kg/ sqm including grouting the joints with white cement and matching pigments etc., complete. 11.41.2 Size of Tile 600x600 mm. | J9: ='Rennovation Measurement'!K46 -> 246.7 | K9: Sqm | L9: 1416.65 | M9: =ROUND(J9*L9,0) -> 349488
A10: 8 | B10: 8.31 | C10: Providing and fixing Ist quality ceramic glazed wall tiles conforming to IS: 15622 (thickness to be specified by the manufacturer), of approved make, in all colours, shades except burgundy, bottle green, black of any size as approved by Engineer-in-Charge, in skirting, risers of steps and dados, over 12 mm thick bed of cement mortar 1:3 (1 cement : 3 coarse sand) and jointing with grey cement slurry @ 3.3kg per sqm, including pointing in white cement mixed with pigment of matching shade complete. | J10: ='Rennovation Measurement'!K55 -> 220.14 | K10: Sqm | L10: 1063.45 | M10: =ROUND(J10*L10,0) -> 234108
A11: 9 | B11: 13.26 | C11: Providing and applying plaster of paris putty of 2 mm thickness over plastered surface to prepare the surface even and smooth complete. | J11: ='Rennovation Measurement'!K75 -> 559.9 | K11: Sqm | L11: 214.3 | M11: =ROUND(J11*L11,0) -> 119987
A12: 10 | B12: 13.85 | C12: Applying priming coats with primer of approved brand and manufacture, having low VOC (Volatile Organic Compound ) content 13.85.3 With water thinnable cement primer on wall surface having VOC content less than 50 grams/litre | J12: ='Rennovation Measurement'!K79 -> 2399.8 | K12: Sqm | L12: 64.45 | M12: =ROUND(J12*L12,0) -> 154667 | Q12: =21.5+21.5+13+13 -> 69 | R12: 3.2 | S12: =Q12*R12*2 -> 441.6 | T12: =21.5*2*3.2 -> 137.6 | V12: 9.75*2*3.2 | W12: =9.75*4*3.2 -> 124.8 | Z12: 21.5 | AA12: 13 | AB12: 3.2
A13: 11 | B13: 13.83 | C13: Wall painting with premium acrylic emulsion paint of interior grade, having VOC (Volatile Organic Compound ) content less than 50 grams/ litre of approved brand and manufacture, including applying additional coats wherever required to achieve even shade and colour. 13.83.2 Two coats | J13: ='Rennovation Measurement'!K200 -> 2217.57 | K13: Sqm | L13: 121.55 | M13: =ROUND(J13*L13,0) -> 269546 | Q13: 2.15 | R13: 1.5 | S13: =Q13*R13*13*2 -> 83.85 | T13: =R13*Q13*8 -> 25.8 | W13: =0.81*2.1*8 -> 13.608 | Z13: 21.5 | AA13: 13 | AB13: 3.2
A14: 12 | B14: 13.48A | C14: Finishing walls with 100% Premium acrylic emulsion paint having VOC less than 50 gm/litre and UV resistance as per IS 15489:2004, Alkali & fungal resistance, dirt resistance exterior paint of required shade (Company Depot Tinted) with silicon additives. 13.48A.1 New work (Two or more coats applied @ 1.43 litre/ 10 sqm. Over and including priming coat of exterior primer applied @ 0.90 litre/10 sqm. | J14: ='Rennovation Measurement'!K220 -> 559.9 | K14: Sqm | L14: 154.45 | M14: =ROUND(J14*L14,0) -> 86477
A15: 13 | B15: ='AType Cottage'!B27 -> 15.12 | C15: ='AType Cottage'!C27 -> Dismantling doors, windows and clerestory windows (steel or wood) shutter including chowkhats, architrave, holdfasts etc. complete and stacking within 50 metres lead : 15.12.1Of area 3 sq. metres and below | J15: ='Rennovation Measurement'!K225 -> 11 | K15: each | L15: ='AType Cottage'!M31 -> 302.7 | M15: =ROUND(J15*L15,0) -> 3330
A16: 14 | B16: ='AType Cottage'!B6 -> 9.1 | C16: ='AType Cottage'!C6 -> Providing wood work in frames of doors, windows, clerestory windows and other frames, wrought framed and fixed in position with hold fast lugs or with dash fasteners of required dia & length (hold fast lugs or dash fastener shall be paid for separately). 9.1.3 Kiln seasoned and chemically treated hollock wood | J16: ='Rennovation Measurement'!K230 -> 0.36 | K16: ='AType Cottage'!L11 -> cum | L16: ='AType Cottage'!M11 -> 74199.7 | M16: =ROUND(J16*L16,0) -> 26712
A17: 15 | B17: ='AType Cottage'!B12 -> 9.5 | C17: ='AType Cottage'!C12 -> Providing and fixing panelled or panelled and glazed shutters for doors, windows and clerestory windows, fixing with butt hinges of required size with necessary screws, excluding panelling which will be paid for separately, all complete as per direction of Engineer-in-charge. (Note:- Butt hinges and necessary screws shall be paid separately) 9.5.2 Kiln seasoned and chemically treated hollock wood 9.5.2.1 35 mm thick shutters | J17: ='Rennovation Measurement'!K235 -> 16.7 | K17: Sqm | L17: ='AType Cottage'!M17 -> 2511.95 | M17: =ROUND(J17*L17,0) -> 41950
A18: 16 | B18: 10.17 | C18: Providing and fixing M.S. fan clamp type I or II of 16 mm dia M.S. bar, bent to shape with hooked ends in R.C.C. slabs or beams during laying, including painting the exposed portion of loop, all as per standard design complete. | J18: ='Rennovation Measurement'!K238 -> 2 | K18: Each | L18: 185.95 | M18: =ROUND(J18*L18,0) -> 372
A19: 17 | B19: 10.14 | C19: Providing and fixing pressed steel door frames conforming to IS: 4351, manufactured from commercial mild steel sheet of 1.60 mm thickness, including hinges, jamb, lock jamb, bead and if required angle threshold of mild steel angle of section 50x25 mm, or base ties of 1.60 mm, pressed mild steel welded or rigidly fixed together by mechanical means, including M.S. pressed butt hinges 2.5 mm thick with mortar guards, lock strike-plate and shock absorbers as specified and applying a coat of approved steel primer after pre-treatment of the surface as directed by Engineer-in-charge: 10.14.1.1 Fixing with adjustable lugs with split end tail to each jamb | J19: ='Rennovation Measurement'!K241 -> 10.5 | K19: Rm | L19: 444.5 | M19: =ROUND(J19*L19,0) -> 4667
A20: 18 | B20: 9.2 | C20: Providing and fixing ISI marked flush door shutters conforming to IS : 2202 (Part I) decorative type, core of block board construction with frame of 1st class hard wood and well matched teak 3 ply veneering with vertical grains or cross bands and face veneers on both faces of shutters. 9.20.1 35 mm thick including ISI marked Stainless Steel butt hinges with necessary screws. | J20: ='Rennovation Measurement'!K244 -> 4.2 | K20: Sqm | L20: 3086.1 | M20: =ROUND(J20*L20,0) -> 12962
A21: 19 | B21: 9.96 | C21: Providing and fixing aluminium sliding door bolts, ISI marked anodised (anodic coating not less than grade AC 10 as per IS : 1868), transparent or dyed to required colour or shade, with nuts and screws etc. complete 9.96.1 300x16 mm | J21: ='Rennovation Measurement'!K247 -> 4 | K21: Each | L21: 260.3 | M21: =ROUND(J21*L21,0) -> 1041
A22: 20 | B22: 9.97 | C22: Providing and fixing aluminium tower bolts, ISI marked, anodised (anodic coating not less than grade AC 10 as per IS : 1868 ) transparent or dyed to required colour or shade, with necessary screws etc. complete : 9.97.1 300x10 mm | J22: ='Rennovation Measurement'!K250 -> 2 | K22: Each | L22: 117.65 | M22: =ROUND(J22*L22,0) -> 235
A23: 21 | B23: 9.1 | C23: Providing and fixing aluminium handles, ISI marked, anodised (anodic coating not less than grade AC 10 as per IS : 1868) transparent or dyed to required colour or shade, with necessary screws etc. complete 9.100.1 125 mm | J23: 2 | K23: Each | L23: 60.05 | M23: =ROUND(J23*L23,0) -> 120
A24: 22 | B24: 9.119 | C24: Providing and fixing factory made P.V.C. door frame of size 50x47 mm with awall thickness of 5 mm, made out of extruded 5mm rigid PVC foam sheet, mitred at corners and joined with 2 Nos of 150 mm long brackets of 15x15 mm M.S. square tube, the vertical door frame profiles to be reinforced with 19x19 mm M.S. square tube of 19 gauge, EPDM rubber gasket weather seal to be provided through out the frame. The door frame to be fixed to the wall using M.S. screws of 65/100 mm size, complete as per manufacturer’s specification and direction of Engineerin- Charge. | J24: ='Rennovation Measurement'!K258 -> 69.3 | K24: R.M | L24: 408.25 | M24: =ROUND(J24*L24,0) -> 28292
A25: 23 | B25: 9.12 | C25: Providing and fixing factory made panel PVC door shutter consisting of frame made out of M.S. tubes of 19 gauge thickness and size of 19 mm x 19 mm for styles and 15x15 mm for top & bottom rails. M.S. frame shall have a coat of steel primers of approved make and manufacture.M.S. frame covered with 5 mm thick heat moulded PVC 'C' channel of size 30 mm thickness, 70 mm width out of which 50 mm shall be flat and 20 mm shall be tapered in 45 degree angle on both side forming styles and 5 mm thick, 95 mm wide PVC sheet out of which 75mm shall be flat and 20 mm shall be tapered in 45 degree on the inner side to form top and bottom rail and 115 mm wide PVC sheet out of which 75 mm shall be flat and 20 mm shall be tapered on both sides to form lock rail. Top, bottom and lock rails shall be provided both side of the panel. 10 mm (5 mm x 2 ) thick, 20 mm wide cross PVC sheet be provided as gap insert for top rail & bottom rail, paneling of 5 mm thick both side PVC sheet to be fitted in the M.S. frame welded/ sealed to the styles & rails with 7 mm (5 mm+2 mm) thick x 15 mm wide PVC sheet beading on inner side, and joined together with solvent cement adhesive. An additional 5 mm thick PVC strip of 20 mm width is to be stuck on the interior side of the 'C' Channel using PVC solvent adhesive etc. complete as per direction of Engineer-in-charge, manufacturer's specification & drawing. 9.120.1 30 mm thick plain PVC door shutters | J25: ='Rennovation Measurement'!K263 -> 22.05 | K25: Sqm | L25: 2455.1 | M25: =ROUND(J25*L25,0) -> 54135
A26: 24 | B26: 10.16 | C26: Steel work in built up tubular (round, square or rectangular hollow tubes etc.) trusses etc., including cutting, hoisting, fixing in position and applying a priming coat of approved steel primer, including welding and bolted with special shaped washers etc. complete. 10.16.2 Hot finished seamless type tubes (60x60x3.2) | J26: ='Rennovation Measurement'!K267 -> 281 | K26: Kg | L26: 168.95 | M26: =ROUND(J26*L26,0) -> 47475
A27: 25 | B27: 12.50 | C27: Providing and fixing precoated galvanised iron profile sheets (size, shape and pitch of corrugation as approved by Engineer-in-charge) 0.50 mm (+ 0.05 %) total coated thickness with zinc coating 120 grams per sqm as per IS: 277, in 240 mpa steel grade, 5-7 microns epoxy primer on both side of the sheet and polyester top coat 15-18 microns. Sheet should have protective guard film of 25 microns minimum to avoid scratches during transportation and should be supplied in single length upto 12 metre or as desired by Engineer in-charge. The sheet shall be fixed using self drilling /self tapping screws of size (5.5x 55 mm) with EPDM seal, complete upto any pitch in horizontal/ vertical or curved surfaces, excluding the cost of purlins, rafters and trusses and including cutting to size and shape wherever required. | J27: ='Rennovation Measurement'!K271 -> 237.2 | K27: sqm | L27: 671.55 | M27: =ROUND(J27*L27,0) -> 159292 | P27: =SQRT(((R27)^2)+((S27)^2)) -> 3.982 | Q27: =(5.2+0.5+0.5)/2 -> 3.1 | R27: 2.5 | S27: =Q27 -> 3.1
A28: 26 | B28: 12.4.2 | C28: Providing ridges or hips of width 60 cm overall width plain G.S. sheet fixed with polymer coated J or L hooks, bolts and nuts 8 mm dia G.I. limpet and bitumen washers complete. 12.4.2 / 0.63 mm thick with zinc coating not less than 275 gm/m2 | J28: ='Rennovation Measurement'!K274 -> 20.5 | K28: Rm | L28: 750.85 | M28: =ROUND(J28*L28,0) -> 15392
A29: 27 | B29: 12.52 | C29: Providing and fixing tiled false ceiling of specified materials of size 595x595 mm in true horizontal level, suspended on inter locking metal grid of hot dipped galvanized steel sections ( galvanized @ 120 grams/ sqm, both side inclusive) consisting of main "T" runner with suitably spaced joints to get required length and of size 24x38 mm made from 0.30 mm thick (minimum) sheet, spaced at 1200 mm center to center and cross "T" of size 24x25 mm made of 0.30 mm thick (minimum) sheet, 1200 mm long spaced between main "T" at 600 mm center to center to form a grid of 1200x600 mm and secondary cross "T" of length 600 mm and size 24x25 mm made of 0.30 mm thick (minimum) sheet to be interlocked at middle of the 1200x600 mm panel to form grids of 600x600 mm and wall angle of size 24x24x0.3 mm and laying false ceiling tiles of approved texture in the grid including, required cutting/making, opening for services like diffusers, grills, light fittings, fixtures, smoke detectors etc. Main"T" runners to be suspended from ceiling using GI slotted cleats ofsize 27 x 37 x 25 x1.6 mm fixed to ceiling with 12.5 mm dia and 50mm long dash fasteners, 4 mm GI adjustable rods with galvanisedbutterfly level clips of size 85 x 30 x 0.8 mm spaced at 1200 mmcenter to center along main T, bottom exposed width of 24 mm of allT-sections shall be pre-painted with polyester paint, all complete forall heights as per specifications, drawings and as rected byEngineer-in-charge. 12.52.3 12.5 mm thick square edge PVC Laminated Gypsum Tile of size 595x595 mm, made of Gypsum plasterboard, manufactured from natural gypsum as per IS 2095 part I and laminated with white 0.16mm thick fire retardant PVC film on the face side and 12micron metalized polyester on the back side with all edges sealed with | J29: ='Rennovation Measurement'!K282 -> 146.92 | K29: Sqm | L29: 1948.95 | M29: =ROUND(J29*L29,0) -> 286340
A30: 28 | B30: 16.78 | C30: Construction of granular sub-base by providing close graded Material conforming to specifications, mixing in a mechanical mix plant at OMC, carriage of mixed material by tippers to work site, for all leads & lifts, spreading in uniform layers of specified thickness with motor grader on prepared surface and compacting with vibratory power roller to achieve the desired density, complete as per specifications and directions of Engineer-in-Charge. 16.78.1 With material conforming to Grade-I (size range 75 mm to 0.075 mm) having CBR Value-30 | J30: ='Rennovation Measurement'!K285 -> 23.65 | K30: Cum | L30: 2658.1 | M30: =ROUND(J30*L30,0) -> 62864
A31: 29 | B31: 16.68 | C31: Providing and laying 60mm thick factory made cement concrete interlocking paver block of M -30 grade made by block making machine with strong vibratory compaction, of approved size, design & shape, laid in required colour and pattern over and including 50mm thick compacted bed of coarse sand, filling the joints with line sand etc. all complete as per the direction of Engineer-in-charge. | J31: ='Rennovation Measurement'!K288 -> 236.5 | K31: Sqm | L31: 951 | M31: =ROUND(J31*L31,0) -> 224912
A32: 30 | B32: 22.6 | C32: {='Rennovation Measurement'!C289:C289} -> Providing and laying water proofing treatment on roofs of slabs by applying cement slurry mixed with water proofing cement compound consisting of applying: (a) after surface preparation, first layer of slurry of cement @ 0.488 kg/sqm mixed with water proofing cement compound @ 0.253 kg/sqm. (b) laying second layer of Fibre glass cloth when the first layer is still green. Overlaps of joints of fibre cloth should not be less than 10 cm. (c) third layer of 1.5 mm thickness consisting of slurry of cement @ 1.289 kg/sqm mixed with water proofing cement compound @ 0.670 kg/sqm and coarse sand @ 1.289 kg/sqm. This will be allowed to air cure for 4 hours followed by water curing for 48 hours. The entire treatment will be taken upto 30 cm on parapet wall and tucked into groove in parapet all around. (d) fourth and final layer of brick tiling with cement mortar (which will be paid for separately. For the purpose of measurement the entire treated surface will be measured. | J32: ='Rennovation Measurement'!K291 -> 198 | K32: Sqm | L32: 585.5 | M32: =ROUND(J32*L32,0) -> 115929
A33: 31 | B33: {='Rennovation Measurement'!B293:B293} -> 5.22.6.A | C33: {='Rennovation Measurement'!C292:C292 & 'Rennovation Measurement'!C293:C293} -> Steel reinforcement for R.C.C. work including straightening, cutting, bending, placing in position and binding all complete above plinth level.Thermo-Mechanically Treated bars of grade Fe-500D or more. | J33: ='Rennovation Measurement'!K296 -> 65.1 | K33: kg | L33: 89.65 | M33: =ROUND(J33*L33,0) -> 5836
A34: 32 | B34: {='Rennovation Measurement'!B297:B297} -> 5.9.3 | C34: {='Rennovation Measurement'!C297:C297} -> Suspended floors, roofs, landings, balconies and access platform | J34: ='Rennovation Measurement'!K299 -> 7.5 | K34: Sqm | L34: ='Rennovation Measurement'!M299 -> 766.55 | M34: =ROUND(J34*L34,0) -> 5749
A35: 33 | B35: ='Rennovation Measurement'!B300 -> 5.3 | C35: {='Rennovation Measurement'!C300:C300} -> Reinforced cement concrete work in beams, suspended floors, roofs having slope up to 15° landings, balconies, shelves, chajjas, lintels, bands, plain window sills, staircases and spiral stair cases above plinth level up to floor five level, excluding the cost of centering, shuttering, finishing and reinforcement with 1:1.5:3 (1 cement : 1.5 coarse sand(zone-III) derived from natural sources : 3 graded stone aggregate 20 mm nominal size derived from natural sources). | J35: ='Rennovation Measurement'!K302 -> 0.75 | K35: cum | L35: ='Rennovation Measurement'!M302 -> 10719.3 | M35: =ROUND(J35*L35,0) -> 8039
A36: 34 | B36: 6.3 | C36: {='Rennovation Measurement'!C303:C303} -> Brick work with common burnt clay machine moulded perforated bricks of class designation 12.5 conforming to IS: 2222 in superstructure above plinth level up to floor five level in cement mortar 1:6 (1 cement : 6 coarse sand) : 6.3.1 With F.P.S.(non modular) bricks | J36: ='Rennovation Measurement'!K305 -> 3.45 | K36: cum | L36: 8030.6 | M36: =ROUND(J36*L36,0) -> 27706
A37: 35 | B37: ='Rennovation Measurement'!B306 -> 13.14 | C37: {='Rennovation Measurement'!C306:C306} -> 15 mm cement plaster 1:2 (1 cement : 2 stone dust) on the rough side of single or half brick wall.: | J37: ='Rennovation Measurement'!K308 -> 68.97 | K37: cum | L37: 376.65 | M37: =ROUND(J37*L37,0) -> 25978
A38: 36 | B38: ='Rennovation Measurement'!B309 -> 9.48 | C38: {='Rennovation Measurement'!C309:C309} -> Providing and fixing M.S. grills of required pattern in frames of windows etc. with M.S. flats, square or round bars etc. including priming coat with approved steel primer all complete. 9.48.2 Fixed to openings /wooden frames with rawl plugs screws etc. | J38: ='Rennovation Measurement'!K311 -> 975 | K38: cum | L38: 197.7 | M38: =ROUND(J38*L38,0) -> 192758
A39: TOTAL= | M39: =ROUND(SUM(M3:M35),0) -> 2357162
A40: SAY= | M40: =M39 -> 2357162
...

Sheet AType Cottage
A1: Name of Work :- Repairing and Renovation of Circuit House at Bokakhat Co District under Golaghat District
A2: (Rates are quoted from DSR (civil) of 2021)
A3: DETAIL ESTIMATE
A4: SL. No. | B4: CODE NO | C4: PARTICULARS | K4: QTY | L4: Unit | M4: RATE | N4: AMOUNT
A6: 1 | B6: 9.1 | C6: Providing wood work in frames of doors, windows, clerestory windows and other frames, wrought framed and fixed in position with hold fast lugs or with dash fasteners of required dia & length (hold fast lugs or dash fastener shall be paid for separately). 9.1.3 Kiln seasoned and chemically treated hollock wood
C7: Quantity
C8: Door, D1 | D8: 1 | E8: x | F8: =2.1+2.1+1.2 -> 5.4 | G8: x | H8: 0.075 | I8: x | J8: 0.1 | K8: =D8*F8*H8*J8 -> 0.041 | L8: cum
C9: W1 | D9: 4 | F9: =1.8*2+1.5*2 -> 6.6 | G9: x | H9: 0.08 | I9: x | J9: 0.1 | K9: =D9*F9*H9*J9 -> 0.211 | L9: cum
C10: V | D10: 5 | F10: =0.9*2+0.45*2 -> 2.7 | G10: x | H10: 0.08 | I10: x | J10: 0.1 | K10: =D10*F10*H10*J10 -> 0.108 | L10: cum
C11: Total | K11: =SUM(K8:K10) -> 0.36 | L11: cum | M11: 74199.7 | N11: =K11*M11 -> 26711.89
